Workbook

Sheet Auswertung
B1: Satz / Modell | C1: Inhalt | D1: Punkte [0-10] | E1: Punkte kumuliert | G1: Satz | H1: d32_el2_dl2_ff128-ep500 | I1: d64_el1_dl1_ff64-ep1000 | J1: d64_el2_dl2_ff64-ep500 | K1: d64_el2_dl2_ff64-ep1000 | L1: d64_el2_dl2_ff128-ep1000 | M1: d64_el3_dl3_ff128-ep1000 | O1: d32_el2_dl2_ff128-ep500 | P1: d64_el1_dl1_ff64-ep1000 | Q1: d64_el2_dl2_ff64-ep500 | R1: d64_el2_dl2_ff64-ep1000 | S1: d64_el2_dl2_ff128-ep1000 | T1: d64_el3_dl3_ff128-ep1000 | V1: d32_el2_dl2_ff128-ep500 | W1: d64_el1_dl1_ff64-ep1000 | X1: d64_el2_dl2_ff64-ep500 | Y1: d64_el2_dl2_ff64-ep1000 | Z1: d64_el2_dl2_ff128-ep1000 | AA1: d64_el3_dl3_ff128-ep1000
A2: 0 | B2: 1 | C2: Guten Morgen! | E2: =D2 -> 0 | G2: 1 | H2: {=INDEX($D$2:$D$701, (ROW()-ROW($G$2))*7 + (COLUMN()-COLUMN($G$2)) + 1)} -> 5 | I2: {=INDEX($D$2:$D$701, (ROW()-ROW($G$2))*7 + (COLUMN()-COLUMN($G$2)) + 1)} -> 1 | J2: {=INDEX($D$2:$D$701, (ROW()-ROW($G$2))*7 + (COLUMN()-COLUMN($G$2)) + 1)} -> 0 | K2: {=INDEX($D$2:$D$701, (ROW()-ROW($G$2))*7 + (COLUMN()-COLUMN($G$2)) + 1)} -> 0 | L2: {=INDEX($D$2:$D$701, (ROW()-ROW($G$2))*7 + (COLUMN()-COLUMN($G$2)) + 1)} -> 1 | M2: {=INDEX($D$2:$D$701, (ROW()-ROW($G$2))*7 + (COLUMN()-COLUMN($G$2)) + 1)} -> 0 | O2: =IF(H2=MAX(Tabelle4[[#This Row],[d32_el2_dl2_ff128-ep500]:[d64_el3_dl3_ff128-ep1000]]),1,0) -> 1 | P2: =IF(I2=MAX(Tabelle4[[#This Row],[d32_el2_dl2_ff128-ep500]:[d64_el3_dl3_ff128-ep1000]]),1,0) -> 0 | Q2: =IF(J2=MAX(Tabelle4[[#This Row],[d32_el2_dl2_ff128-ep500]:[d64_el3_dl3_ff128-ep1000]]),1,0) -> 0 | R2: =IF(K2=MAX(Tabelle4[[#This Row],[d32_el2_dl2_ff128-ep500]:[d64_el3_dl3_ff128-ep1000]]),1,0) -> 0 | S2: =IF(L2=MAX(Tabelle4[[#This Row],[d32_el2_dl2_ff128-ep500]:[d64_el3_dl3_ff128-ep1000]]),1,0) -> 0 | T2: =IF(M2=MAX(Tabelle4[[#This Row],[d32_el2_dl2_ff128-ep500]:[d64_el3_dl3_ff128-ep1000]]),1,0) -> 0 | V2: =IF(H2=MIN(Tabelle4[[#This Row],[d32_el2_dl2_ff128-ep500]:[d64_el3_dl3_ff128-ep1000]]),1,0) -> 0 | W2: =IF(I2=MIN(Tabelle4[[#This Row],[d32_el2_dl2_ff128-ep500]:[d64_el3_dl3_ff128-ep1000]]),1,0) -> 0 | X2: =IF(J2=MIN(Tabelle4[[#This Row],[d32_el2_dl2_ff128-ep500]:[d64_el3_dl3_ff128-ep1000]]),1,0) -> 1 | Y2: =IF(K2=MIN(Tabelle4[[#This Row],[d32_el2_dl2_ff128-ep500]:[d64_el3_dl3_ff128-ep1000]]),1,0) -> 1 | Z2: =IF(L2=MIN(Tabelle4[[#This Row],[d32_el2_dl2_ff128-ep500]:[d64_el3_dl3_ff128-ep1000]]),1,0) -> 0 | AA2: =IF(M2=MIN(Tabelle4[[#This Row],[d32_el2_dl2_ff128-ep500]:[d64_el3_dl3_ff128-ep1000]]),1,0) -> 1
A3: 1 | B3: d32_el2_dl2_ff128-ep500 | C3: ['morgen', 'material'] | D3: 5 | E3: =D3 -> 5 | G3: 2 | H3: {=INDEX($D$2:$D$701, (ROW()-ROW($G$2))*7 + (COLUMN()-COLUMN($G$2)) + 1)} -> 7 | I3: {=INDEX($D$2:$D$701, (ROW()-ROW($G$2))*7 + (COLUMN()-COLUMN($G$2)) + 1)} -> 7 | J3: {=INDEX($D$2:$D$701, (ROW()-ROW($G$2))*7 + (COLUMN()-COLUMN($G$2)) + 1)} -> 7 | K3: {=INDEX($D$2:$D$701, (ROW()-ROW($G$2))*7 + (COLUMN()-COLUMN($G$2)) + 1)} -> 7 | L3: {=INDEX($D$2:$D$701, (ROW()-ROW($G$2))*7 + (COLUMN()-COLUMN($G$2)) + 1)} -> 7 | M3: {=INDEX($D$2:$D$701, (ROW()-ROW($G$2))*7 + (COLUMN()-COLUMN($G$2)) + 1)} -> 7 | O3: =IF(H3=MAX(Tabelle4[[#This Row],[d32_el2_dl2_ff128-ep500]:[d64_el3_dl3_ff128-ep1000]]),1,0) -> 1 | P3: =IF(I3=MAX(Tabelle4[[#This Row],[d32_el2_dl2_ff128-ep500]:[d64_el3_dl3_ff128-ep1000]]),1,0) -> 1 | Q3: =IF(J3=MAX(Tabelle4[[#This Row],[d32_el2_dl2_ff128-ep500]:[d64_el3_dl3_ff128-ep1000]]),1,0) -> 1 | R3: =IF(K3=MAX(Tabelle4[[#This Row],[d32_el2_dl2_ff128-ep500]:[d64_el3_dl3_ff128-ep1000]]),1,0) -> 1 | S3: =IF(L3=MAX(Tabelle4[[#This Row],[d32_el2_dl2_ff128-ep500]:[d64_el3_dl3_ff128-ep1000]]),1,0) -> 1 | T3: =IF(M3=MAX(Tabelle4[[#This Row],[d32_el2_dl2_ff128-ep500]:[d64_el3_dl3_ff128-ep1000]]),1,0) -> 1 | V3: =IF(H3=MIN(Tabelle4[[#This Row],[d32_el2_dl2_ff128-ep500]:[d64_el3_dl3_ff128-ep1000]]),1,0) -> 1 | W3: =IF(I3=MIN(Tabelle4[[#This Row],[d32_el2_dl2_ff128-ep500]:[d64_el3_dl3_ff128-ep1000]]),1,0) -> 1 | X3: =IF(J3=MIN(Tabelle4[[#This Row],[d32_el2_dl2_ff128-ep500]:[d64_el3_dl3_ff128-ep1000]]),1,0) -> 1 | Y3: =IF(K3=MIN(Tabelle4[[#This Row],[d32_el2_dl2_ff128-ep500]:[d64_el3_dl3_ff128-ep1000]]),1,0) -> 1 | Z3: =IF(L3=MIN(Tabelle4[[#This Row],[d32_el2_dl2_ff128-ep500]:[d64_el3_dl3_ff128-ep1000]]),1,0) -> 1 | AA3: =IF(M3=MIN(Tabelle4[[#This Row],[d32_el2_dl2_ff128-ep500]:[d64_el3_dl3_ff128-ep1000]]),1,0) -> 1
A4: 2 | B4: d64_el1_dl1_ff64-ep1000 | C4: ['morgen', 'sonne wandern', 'sonne wandern', 'sonne wandern', 'sonne wandern', 'sonne wandern', 'sonne wandern', 'sonne wandern', 'sonne wandern', 'sonne wandern', 'sonne wandern', 'sonne wandern', 'sonne wandern', 'sonne wandern', 'sonne wandern', 'sonne wandern', 'sonne wandern', 'sonne wandern', 'sonne wandern', 'sonne wandern'] | D4: 1 | E4: =D4 -> 1 | G4: 3 | H4: {=INDEX($D$2:$D$701, (ROW()-ROW($G$2))*7 + (COLUMN()-COLUMN($G$2)) + 1)} -> 2 | I4: {=INDEX($D$2:$D$701, (ROW()-ROW($G$2))*7 + (COLUMN()-COLUMN($G$2)) + 1)} -> 4 | J4: {=INDEX($D$2:$D$701, (ROW()-ROW($G$2))*7 + (COLUMN()-COLUMN($G$2)) + 1)} -> 10 | K4: {=INDEX($D$2:$D$701, (ROW()-ROW($G$2))*7 + (COLUMN()-COLUMN($G$2)) + 1)} -> 10 | L4: {=INDEX($D$2:$D$701, (ROW()-ROW($G$2))*7 + (COLUMN()-COLUMN($G$2)) + 1)} -> 9 | M4: {=INDEX($D$2:$D$701, (ROW()-ROW($G$2))*7 + (COLUMN()-COLUMN($G$2)) + 1)} -> 8 | O4: =IF(H4=MAX(Tabelle4[[#This Row],[d32_el2_dl2_ff128-ep500]:[d64_el3_dl3_ff128-ep1000]]),1,0) -> 0 | P4: =IF(I4=MAX(Tabelle4[[#This Row],[d32_el2_dl2_ff128-ep500]:[d64_el3_dl3_ff128-ep1000]]),1,0) -> 0 | Q4: =IF(J4=MAX(Tabelle4[[#This Row],[d32_el2_dl2_ff128-ep500]:[d64_el3_dl3_ff128-ep1000]]),1,0) -> 1 | R4: =IF(K4=MAX(Tabelle4[[#This Row],[d32_el2_dl2_ff128-ep500]:[d64_el3_dl3_ff128-ep1000]]),1,0) -> 1 | S4: =IF(L4=MAX(Tabelle4[[#This Row],[d32_el2_dl2_ff128-ep500]:[d64_el3_dl3_ff128-ep1000]]),1,0) -> 0 | T4: =IF(M4=MAX(Tabelle4[[#This Row],[d32_el2_dl2_ff128-ep500]:[d64_el3_dl3_ff128-ep1000]]),1,0) -> 0 | V4: =IF(H4=MIN(Tabelle4[[#This Row],[d32_el2_dl2_ff128-ep500]:[d64_el3_dl3_ff128-ep1000]]),1,0) -> 1 | W4: =IF(I4=MIN(Tabelle4[[#This Row],[d32_el2_dl2_ff128-ep500]:[d64_el3_dl3_ff128-ep1000]]),1,0) -> 0 | X4: =IF(J4=MIN(Tabelle4[[#This Row],[d32_el2_dl2_ff128-ep500]:[d64_el3_dl3_ff128-ep1000]]),1,0) -> 0 | Y4: =IF(K4=MIN(Tabelle4[[#This Row],[d32_el2_dl2_ff128-ep500]:[d64_el3_dl3_ff128-ep1000]]),1,0) -> 0 | Z4: =IF(L4=MIN(Tabelle4[[#This Row],[d32_el2_dl2_ff128-ep500]:[d64_el3_dl3_ff128-ep1000]]),1,0) -> 0 | AA4: =IF(M4=MIN(Tabelle4[[#This Row],[d32_el2_dl2_ff128-ep500]:[d64_el3_dl3_ff128-ep1000]]),1,0) -> 0
A5: 3 | B5: d64_el2_dl2_ff64-ep500 | C5: ['ich', 'selbst', 'sorgfältig', 'verschwommen'] | D5: 0 | E5: =D5 -> 0 | G5: 4 | H5: {=INDEX($D$2:$D$701, (ROW()-ROW($G$2))*7 + (COLUMN()-COLUMN($G$2)) + 1)} -> 10 | I5: {=INDEX($D$2:$D$701, (ROW()-ROW($G$2))*7 + (COLUMN()-COLUMN($G$2)) + 1)} -> 6 | J5: {=INDEX($D$2:$D$701, (ROW()-ROW($G$2))*7 + (COLUMN()-COLUMN($G$2)) + 1)} -> 7 | K5: {=INDEX($D$2:$D$701, (ROW()-ROW($G$2))*7 + (COLUMN()-COLUMN($G$2)) + 1)} -> 7 | L5: {=INDEX($D$2:$D$701, (ROW()-ROW($G$2))*7 + (COLUMN()-COLUMN($G$2)) + 1)} -> 5 | M5: {=INDEX($D$2:$D$701, (ROW()-ROW($G$2))*7 + (COLUMN()-COLUMN($G$2)) + 1)} -> 10 | O5: =IF(H5=MAX(Tabelle4[[#This Row],[d32_el2_dl2_ff128-ep500]:[d64_el3_dl3_ff128-ep1000]]),1,0) -> 1 | P5: =IF(I5=MAX(Tabelle4[[#This Row],[d32_el2_dl2_ff128-ep500]:[d64_el3_dl3_ff128-ep1000]]),1,0) -> 0 | Q5: =IF(J5=MAX(Tabelle4[[#This Row],[d32_el2_dl2_ff128-ep500]:[d64_el3_dl3_ff128-ep1000]]),1,0) -> 0 | R5: =IF(K5=MAX(Tabelle4[[#This Row],[d32_el2_dl2_ff128-ep500]:[d64_el3_dl3_ff128-ep1000]]),1,0) -> 0 | S5: =IF(L5=MAX(Tabelle4[[#This Row],[d32_el2_dl2_ff128-ep500]:[d64_el3_dl3_ff128-ep1000]]),1,0) -> 0 | T5: =IF(M5=MAX(Tabelle4[[#This Row],[d32_el2_dl2_ff128-ep500]:[d64_el3_dl3_ff128-ep1000]]),1,0) -> 1 | V5: =IF(H5=MIN(Tabelle4[[#This Row],[d32_el2_dl2_ff128-ep500]:[d64_el3_dl3_ff128-ep1000]]),1,0) -> 0 | W5: =IF(I5=MIN(Tabelle4[[#This Row],[d32_el2_dl2_ff128-ep500]:[d64_el3_dl3_ff128-ep1000]]),1,0) -> 0 | X5: =IF(J5=MIN(Tabelle4[[#This Row],[d32_el2_dl2_ff128-ep500]:[d64_el3_dl3_ff128-ep1000]]),1,0) -> 0 | Y5: =IF(K5=MIN(Tabelle4[[#This Row],[d32_el2_dl2_ff128-ep500]:[d64_el3_dl3_ff128-ep1000]]),1,0) -> 0 | Z5: =IF(L5=MIN(Tabelle4[[#This Row],[d32_el2_dl2_ff128-ep500]:[d64_el3_dl3_ff128-ep1000]]),1,0) -> 1 | AA5: =IF(M5=MIN(Tabelle4[[#This Row],[d32_el2_dl2_ff128-ep500]:[d64_el3_dl3_ff128-ep1000]]),1,0) -> 0
A6: 4 | B6: d64_el2_dl2_ff64-ep1000 | C6: ['ich', 'für', 'ich', 'selbst', 'sorgfältig', 'verschwommen'] | D6: 0 | E6: =D6 -> 0 | G6: 5 | H6: {=INDEX($D$2:$D$701, (ROW()-ROW($G$2))*7 + (COLUMN()-COLUMN($G$2)) + 1)} -> 9 | I6: {=INDEX($D$2:$D$701, (ROW()-ROW($G$2))*7 + (COLUMN()-COLUMN($G$2)) + 1)} -> 8 | J6: {=INDEX($D$2:$D$701, (ROW()-ROW($G$2))*7 + (COLUMN()-COLUMN($G$2)) + 1)} -> 9 | K6: {=INDEX($D$2:$D$701, (ROW()-ROW($G$2))*7 + (COLUMN()-COLUMN($G$2)) + 1)} -> 9 | L6: {=INDEX($D$2:$D$701, (ROW()-ROW($G$2))*7 + (COLUMN()-COLUMN($G$2)) + 1)} -> 8 | M6: {=INDEX($D$2:$D$701, (ROW()-ROW($G$2))*7 + (COLUMN()-COLUMN($G$2)) + 1)} -> 9 | O6: =IF(H6=MAX(Tabelle4[[#This Row],[d32_el2_dl2_ff128-ep500]:[d64_el3_dl3_ff128-ep1000]]),1,0) -> 1 | P6: =IF(I6=MAX(Tabelle4[[#This Row],[d32_el2_dl2_ff128-ep500]:[d64_el3_dl3_ff128-ep1000]]),1,0) -> 0 | Q6: =IF(J6=MAX(Tabelle4[[#This Row],[d32_el2_dl2_ff128-ep500]:[d64_el3_dl3_ff128-ep1000]]),1,0) -> 1 | R6: =IF(K6=MAX(Tabelle4[[#This Row],[d32_el2_dl2_ff128-ep500]:[d64_el3_dl3_ff128-ep1000]]),1,0) -> 1 | S6: =IF(L6=MAX(Tabelle4[[#This Row],[d32_el2_dl2_ff128-ep500]:[d64_el3_dl3_ff128-ep1000]]),1,0) -> 0 | T6: =IF(M6=MAX(Tabelle4[[#This Row],[d32_el2_dl2_ff128-ep500]:[d64_el3_dl3_ff128-ep1000]]),1,0) -> 1 | V6: =IF(H6=MIN(Tabelle4[[#This Row],[d32_el2_dl2_ff128-ep500]:[d64_el3_dl3_ff128-ep1000]]),1,0) -> 0 | W6: =IF(I6=MIN(Tabelle4[[#This Row],[d32_el2_dl2_ff128-ep500]:[d64_el3_dl3_ff128-ep1000]]),1,0) -> 1 | X6: =IF(J6=MIN(Tabelle4[[#This Row],[d32_el2_dl2_ff128-ep500]:[d64_el3_dl3_ff128-ep1000]]),1,0) -> 0 | Y6: =IF(K6=MIN(Tabelle4[[#This Row],[d32_el2_dl2_ff128-ep500]:[d64_el3_dl3_ff128-ep1000]]),1,0) -> 0 | Z6: =IF(L6=MIN(Tabelle4[[#This Row],[d32_el2_dl2_ff128-ep500]:[d64_el3_dl3_ff128-ep1000]]),1,0) -> 1 | AA6: =IF(M6=MIN(Tabelle4[[#This Row],[d32_el2_dl2_ff128-ep500]:[d64_el3_dl3_ff128-ep1000]]),1,0) -> 0
A7: 5 | B7: d64_el2_dl2_ff128-ep1000 | C7: ['früh', 'entlassen'] | D7: 1 | E7: =D7 -> 1 | G7: 6 | H7: {=INDEX($D$2:$D$701, (ROW()-ROW($G$2))*7 + (COLUMN()-COLUMN($G$2)) + 1)} -> 5 | I7: {=INDEX($D$2:$D$701, (ROW()-ROW($G$2))*7 + (COLUMN()-COLUMN($G$2)) + 1)} -> 2 | J7: {=INDEX($D$2:$D$701, (ROW()-ROW($G$2))*7 + (COLUMN()-COLUMN($G$2)) + 1)} -> 1 | K7: {=INDEX($D$2:$D$701, (ROW()-ROW($G$2))*7 + (COLUMN()-COLUMN($G$2)) + 1)} -> 1 | L7: {=INDEX($D$2:$D$701, (ROW()-ROW($G$2))*7 + (COLUMN()-COLUMN($G$2)) + 1)} -> 5 | M7: {=INDEX($D$2:$D$701, (ROW()-ROW($G$2))*7 + (COLUMN()-COLUMN($G$2)) + 1)} -> 5 | O7: =IF(H7=MAX(Tabelle4[[#This Row],[d32_el2_dl2_ff128-ep500]:[d64_el3_dl3_ff128-ep1000]]),1,0) -> 1 | P7: =IF(I7=MAX(Tabelle4[[#This Row],[d32_el2_dl2_ff128-ep500]:[d64_el3_dl3_ff128-ep1000]]),1,0) -> 0 | Q7: =IF(J7=MAX(Tabelle4[[#This Row],[d32_el2_dl2_ff128-ep500]:[d64_el3_dl3_ff128-ep1000]]),1,0) -> 0 | R7: =IF(K7=MAX(Tabelle4[[#This Row],[d32_el2_dl2_ff128-ep500]:[d64_el3_dl3_ff128-ep1000]]),1,0) -> 0 | S7: =IF(L7=MAX(Tabelle4[[#This Row],[d32_el2_dl2_ff128-ep500]:[d64_el3_dl3_ff128-ep1000]]),1,0) -> 1 | T7: =IF(M7=MAX(Tabelle4[[#This Row],[d32_el2_dl2_ff128-ep500]:[d64_el3_dl3_ff128-ep1000]]),1,0) -> 1 | V7: =IF(H7=MIN(Tabelle4[[#This Row],[d32_el2_dl2_ff128-ep500]:[d64_el3_dl3_ff128-ep1000]]),1,0) -> 0 | W7: =IF(I7=MIN(Tabelle4[[#This Row],[d32_el2_dl2_ff128-ep500]:[d64_el3_dl3_ff128-ep1000]]),1,0) -> 0 | X7: =IF(J7=MIN(Tabelle4[[#This Row],[d32_el2_dl2_ff128-ep500]:[d64_el3_dl3_ff128-ep1000]]),1,0) -> 1 | Y7: =IF(K7=MIN(Tabelle4[[#This Row],[d32_el2_dl2_ff128-ep500]:[d64_el3_dl3_ff128-ep1000]]),1,0) -> 1 | Z7: =IF(L7=MIN(Tabelle4[[#This Row],[d32_el2_dl2_ff128-ep500]:[d64_el3_dl3_ff128-ep1000]]),1,0) -> 0 | AA7: =IF(M7=MIN(Tabelle4[[#This Row],[d32_el2_dl2_ff128-ep500]:[d64_el3_dl3_ff128-ep1000]]),1,0) -> 0
A8: 6 | B8: d64_el3_dl3_ff128-ep1000 | C8: ['ich', 'selbst', 'ich', 'sehen'] | D8: 0 | E8: =D8 -> 0 | G8: 7 | H8: {=INDEX($D$2:$D$701, (ROW()-ROW($G$2))*7 + (COLUMN()-COLUMN($G$2)) + 1)} -> 0 | I8: {=INDEX($D$2:$D$701, (ROW()-ROW($G$2))*7 + (COLUMN()-COLUMN($G$2)) + 1)} -> 1 | J8: {=INDEX($D$2:$D$701, (ROW()-ROW($G$2))*7 + (COLUMN()-COLUMN($G$2)) + 1)} -> 1 | K8: {=INDEX($D$2:$D$701, (ROW()-ROW($G$2))*7 + (COLUMN()-COLUMN($G$2)) + 1)} -> 1 | L8: {=INDEX($D$2:$D$701, (ROW()-ROW($G$2))*7 + (COLUMN()-COLUMN($G$2)) + 1)} -> 0 | M8: {=INDEX($D$2:$D$701, (ROW()-ROW($G$2))*7 + (COLUMN()-COLUMN($G$2)) + 1)} -> 0 | O8: =IF(H8=MAX(Tabelle4[[#This Row],[d32_el2_dl2_ff128-ep500]:[d64_el3_dl3_ff128-ep1000]]),1,0) -> 0 | P8: =IF(I8=MAX(Tabelle4[[#This Row],[d32_el2_dl2_ff128-ep500]:[d64_el3_dl3_ff128-ep1000]]),1,0) -> 1 | Q8: =IF(J8=MAX(Tabelle4[[#This Row],[d32_el2_dl2_ff128-ep500]:[d64_el3_dl3_ff128-ep1000]]),1,0) -> 1 | R8: =IF(K8=MAX(Tabelle4[[#This Row],[d32_el2_dl2_ff128-ep500]:[d64_el3_dl3_ff128-ep1000]]),1,0) -> 1 | S8: =IF(L8=MAX(Tabelle4[[#This Row],[d32_el2_dl2_ff128-ep500]:[d64_el3_dl3_ff128-ep1000]]),1,0) -> 0 | T8: =IF(M8=MAX(Tabelle4[[#This Row],[d32_el2_dl2_ff128-ep500]:[d64_el3_dl3_ff128-ep1000]]),1,0) -> 0 | V8: =IF(H8=MIN(Tabelle4[[#This Row],[d32_el2_dl2_ff128-ep500]:[d64_el3_dl3_ff128-ep1000]]),1,0) -> 1 | W8: =IF(I8=MIN(Tabelle4[[#This Row],[d32_el2_dl2_ff128-ep500]:[d64_el3_dl3_ff128-ep1000]]),1,0) -> 0 | X8: =IF(J8=MIN(Tabelle4[[#This Row],[d32_el2_dl2_ff128-ep500]:[d64_el3_dl3_ff128-ep1000]]),1,0) -> 0 | Y8: =IF(K8=MIN(Tabelle4[[#This Row],[d32_el2_dl2_ff128-ep500]:[d64_el3_dl3_ff128-ep1000]]),1,0) -> 0 | Z8: =IF(L8=MIN(Tabelle4[[#This Row],[d32_el2_dl2_ff128-ep500]:[d64_el3_dl3_ff128-ep1000]]),1,0) -> 1 | AA8: =IF(M8=MIN(Tabelle4[[#This Row],[d32_el2_dl2_ff128-ep500]:[d64_el3_dl3_ff128-ep1000]]),1,0) -> 1
A9: 0 | B9: 2 | C9: Wie geht es dir? | E9: =D9+E2 -> 0 | G9: 8 | H9: {=INDEX($D$2:$D$701, (ROW()-ROW($G$2))*7 + (COLUMN()-COLUMN($G$2)) + 1)} -> 6 | I9: {=INDEX($D$2:$D$701, (ROW()-ROW($G$2))*7 + (COLUMN()-COLUMN($G$2)) + 1)} -> 4 | J9: {=INDEX($D$2:$D$701, (ROW()-ROW($G$2))*7 + (COLUMN()-COLUMN($G$2)) + 1)} -> 5 | K9: {=INDEX($D$2:$D$701, (ROW()-ROW($G$2))*7 + (COLUMN()-COLUMN($G$2)) + 1)} -> 6 | L9: {=INDEX($D$2:$D$701, (ROW()-ROW($G$2))*7 + (COLUMN()-COLUMN($G$2)) + 1)} -> 6 | M9: {=INDEX($D$2:$D$701, (ROW()-ROW($G$2))*7 + (COLUMN()-COLUMN($G$2)) + 1)} -> 6 | O9: =IF(H9=MAX(Tabelle4[[#This Row],[d32_el2_dl2_ff128-ep500]:[d64_el3_dl3_ff128-ep1000]]),1,0) -> 1 | P9: =IF(I9=MAX(Tabelle4[[#This Row],[d32_el2_dl2_ff128-ep500]:[d64_el3_dl3_ff128-ep1000]]),1,0) -> 0 | Q9: =IF(J9=MAX(Tabelle4[[#This Row],[d32_el2_dl2_ff128-ep500]:[d64_el3_dl3_ff128-ep1000]]),1,0) -> 0 | R9: =IF(K9=MAX(Tabelle4[[#This Row],[d32_el2_dl2_ff128-ep500]:[d64_el3_dl3_ff128-ep1000]]),1,0) -> 1 | S9: =IF(L9=MAX(Tabelle4[[#This Row],[d32_el2_dl2_ff128-ep500]:[d64_el3_dl3_ff128-ep1000]]),1,0) -> 1 | T9: =IF(M9=MAX(Tabelle4[[#This Row],[d32_el2_dl2_ff128-ep500]:[d64_el3_dl3_ff128-ep1000]]),1,0) -> 1 | V9: =IF(H9=MIN(Tabelle4[[#This Row],[d32_el2_dl2_ff128-ep500]:[d64_el3_dl3_ff128-ep1000]]),1,0) -> 0 | W9: =IF(I9=MIN(Tabelle4[[#This Row],[d32_el2_dl2_ff128-ep500]:[d64_el3_dl3_ff128-ep1000]]),1,0) -> 1 | X9: =IF(J9=MIN(Tabelle4[[#This Row],[d32_el2_dl2_ff128-ep500]:[d64_el3_dl3_ff128-ep1000]]),1,0) -> 0 | Y9: =IF(K9=MIN(Tabelle4[[#This Row],[d32_el2_dl2_ff128-ep500]:[d64_el3_dl3_ff128-ep1000]]),1,0) -> 0 | Z9: =IF(L9=MIN(Tabelle4[[#This Row],[d32_el2_dl2_ff128-ep500]:[d64_el3_dl3_ff128-ep1000]]),1,0) -> 0 | AA9: =IF(M9=MIN(Tabelle4[[#This Row],[d32_el2_dl2_ff128-ep500]:[d64_el3_dl3_ff128-ep1000]]),1,0) -> 0
A10: 1 | B10: d32_el2_dl2_ff128-ep500 | C10: ['wie frage vergleich'] | D10: 7 | E10: =D10+E3 -> 12 | G10: 9 | H10: {=INDEX($D$2:$D$701, (ROW()-ROW($G$2))*7 + (COLUMN()-COLUMN($G$2)) + 1)} -> 4 | I10: {=INDEX($D$2:$D$701, (ROW()-ROW($G$2))*7 + (COLUMN()-COLUMN($G$2)) + 1)} -> 6 | J10: {=INDEX($D$2:$D$701, (ROW()-ROW($G$2))*7 + (COLUMN()-COLUMN($G$2)) + 1)} -> 0 | K10: {=INDEX($D$2:$D$701, (ROW()-ROW($G$2))*7 + (COLUMN()-COLUMN($G$2)) + 1)} -> 0 | L10: {=INDEX($D$2:$D$701, (ROW()-ROW($G$2))*7 + (COLUMN()-COLUMN($G$2)) + 1)} -> 6 | M10: {=INDEX($D$2:$D$701, (ROW()-ROW($G$2))*7 + (COLUMN()-COLUMN($G$2)) + 1)} -> 6 | O10: =IF(H10=MAX(Tabelle4[[#This Row],[d32_el2_dl2_ff128-ep500]:[d64_el3_dl3_ff128-ep1000]]),1,0) -> 0 | P10: =IF(I10=MAX(Tabelle4[[#This Row],[d32_el2_dl2_ff128-ep500]:[d64_el3_dl3_ff128-ep1000]]),1,0) -> 1 | Q10: =IF(J10=MAX(Tabelle4[[#This Row],[d32_el2_dl2_ff128-ep500]:[d64_el3_dl3_ff128-ep1000]]),1,0) -> 0 | R10: =IF(K10=MAX(Tabelle4[[#This Row],[d32_el2_dl2_ff128-ep500]:[d64_el3_dl3_ff128-ep1000]]),1,0) -> 0 | S10: =IF(L10=MAX(Tabelle4[[#This Row],[d32_el2_dl2_ff128-ep500]:[d64_el3_dl3_ff128-ep1000]]),1,0) -> 1 | T10: =IF(M10=MAX(Tabelle4[[#This Row],[d32_el2_dl2_ff128-ep500]:[d64_el3_dl3_ff128-ep1000]]),1,0) -> 1 | V10: =IF(H10=MIN(Tabelle4[[#This Row],[d32_el2_dl2_ff128-ep500]:[d64_el3_dl3_ff128-ep1000]]),1,0) -> 0 | W10: =IF(I10=MIN(Tabelle4[[#This Row],[d32_el2_dl2_ff128-ep500]:[d64_el3_dl3_ff128-ep1000]]),1,0) -> 0 | X10: =IF(J10=MIN(Tabelle4[[#This Row],[d32_el2_dl2_ff128-ep500]:[d64_el3_dl3_ff128-ep1000]]),1,0) -> 1 | Y10: =IF(K10=MIN(Tabelle4[[#This Row],[d32_el2_dl2_ff128-ep500]:[d64_el3_dl3_ff128-ep1000]]),1,0) -> 1 | Z10: =IF(L10=MIN(Tabelle4[[#This Row],[d32_el2_dl2_ff128-ep500]:[d64_el3_dl3_ff128-ep1000]]),1,0) -> 0 | AA10: =IF(M10=MIN(Tabelle4[[#This Row],[d32_el2_dl2_ff128-ep500]:[d64_el3_dl3_ff128-ep1000]]),1,0) -> 0
A11: 2 | B11: d64_el1_dl1_ff64-ep1000 | C11: ['wie frage vergleich'] | D11: 7 | E11: =D11+E4 -> 8 | G11: 10 | H11: {=INDEX($D$2:$D$701, (ROW()-ROW($G$2))*7 + (COLUMN()-COLUMN($G$2)) + 1)} -> 10 | I11: {=INDEX($D$2:$D$701, (ROW()-ROW($G$2))*7 + (COLUMN()-COLUMN($G$2)) + 1)} -> 10 | J11: {=INDEX($D$2:$D$701, (ROW()-ROW($G$2))*7 + (COLUMN()-COLUMN($G$2)) + 1)} -> 10 | K11: {=INDEX($D$2:$D$701, (ROW()-ROW($G$2))*7 + (COLUMN()-COLUMN($G$2)) + 1)} -> 10 | L11: {=INDEX($D$2:$D$701, (ROW()-ROW($G$2))*7 + (COLUMN()-COLUMN($G$2)) + 1)} -> 10 | M11: {=INDEX($D$2:$D$701, (ROW()-ROW($G$2))*7 + (COLUMN()-COLUMN($G$2)) + 1)} -> 10 | O11: =IF(H11=MAX(Tabelle4[[#This Row],[d32_el2_dl2_ff128-ep500]:[d64_el3_dl3_ff128-ep1000]]),1,0) -> 1 | P11: =IF(I11=MAX(Tabelle4[[#This Row],[d32_el2_dl2_ff128-ep500]:[d64_el3_dl3_ff128-ep1000]]),1,0) -> 1 | Q11: =IF(J11=MAX(Tabelle4[[#This Row],[d32_el2_dl2_ff128-ep500]:[d64_el3_dl3_ff128-ep1000]]),1,0) -> 1 | R11: =IF(K11=MAX(Tabelle4[[#This Row],[d32_el2_dl2_ff128-ep500]:[d64_el3_dl3_ff128-ep1000]]),1,0) -> 1 | S11: =IF(L11=MAX(Tabelle4[[#This Row],[d32_el2_dl2_ff128-ep500]:[d64_el3_dl3_ff128-ep1000]]),1,0) -> 1 | T11: =IF(M11=MAX(Tabelle4[[#This Row],[d32_el2_dl2_ff128-ep500]:[d64_el3_dl3_ff128-ep1000]]),1,0) -> 1 | V11: =IF(H11=MIN(Tabelle4[[#This Row],[d32_el2_dl2_ff128-ep500]:[d64_el3_dl3_ff128-ep1000]]),1,0) -> 1 | W11: =IF(I11=MIN(Tabelle4[[#This Row],[d32_el2_dl2_ff128-ep500]:[d64_el3_dl3_ff128-ep1000]]),1,0) -> 1 | X11: =IF(J11=MIN(Tabelle4[[#This Row],[d32_el2_dl2_ff128-ep500]:[d64_el3_dl3_ff128-ep1000]]),1,0) -> 1 | Y11: =IF(K11=MIN(Tabelle4[[#This Row],[d32_el2_dl2_ff128-ep500]:[d64_el3_dl3_ff128-ep1000]]),1,0) -> 1 | Z11: =IF(L11=MIN(Tabelle4[[#This Row],[d32_el2_dl2_ff128-ep500]:[d64_el3_dl3_ff128-ep1000]]),1,0) -> 1 | AA11: =IF(M11=MIN(Tabelle4[[#This Row],[d32_el2_dl2_ff128-ep500]:[d64_el3_dl3_ff128-ep1000]]),1,0) -> 1
A12: 3 | B12: d64_el2_dl2_ff64-ep500 | C12: ['wie frage vergleich'] | D12: 7 | E12: =D12+E5 -> 7 | G12: 11 | H12: {=INDEX($D$2:$D$701, (ROW()-ROW($G$2))*7 + (COLUMN()-COLUMN($G$2)) + 1)} -> 6 | I12: {=INDEX($D$2:$D$701, (ROW()-ROW($G$2))*7 + (COLUMN()-COLUMN($G$2)) + 1)} -> 6 | J12: {=INDEX($D$2:$D$701, (ROW()-ROW($G$2))*7 + (COLUMN()-COLUMN($G$2)) + 1)} -> 6 | K12: {=INDEX($D$2:$D$701, (ROW()-ROW($G$2))*7 + (COLUMN()-COLUMN($G$2)) + 1)} -> 6 | L12: {=INDEX($D$2:$D$701, (ROW()-ROW($G$2))*7 + (COLUMN()-COLUMN($G$2)) + 1)} -> 6 | M12: {=INDEX($D$2:$D$701, (ROW()-ROW($G$2))*7 + (COLUMN()-COLUMN($G$2)) + 1)} -> 4 | O12: =IF(H12=MAX(Tabelle4[[#This Row],[d32_el2_dl2_ff128-ep500]:[d64_el3_dl3_ff128-ep1000]]),1,0) -> 1 | P12: =IF(I12=MAX(Tabelle4[[#This Row],[d32_el2_dl2_ff128-ep500]:[d64_el3_dl3_ff128-ep1000]]),1,0) -> 1 | Q12: =IF(J12=MAX(Tabelle4[[#This Row],[d32_el2_dl2_ff128-ep500]:[d64_el3_dl3_ff128-ep1000]]),1,0) -> 1 | R12: =IF(K12=MAX(Tabelle4[[#This Row],[d32_el2_dl2_ff128-ep500]:[d64_el3_dl3_ff128-ep1000]]),1,0) -> 1 | S12: =IF(L12=MAX(Tabelle4[[#This Row],[d32_el2_dl2_ff128-ep500]:[d64_el3_dl3_ff128-ep1000]]),1,0) -> 1 | T12: =IF(M12=MAX(Tabelle4[[#This Row],[d32_el2_dl2_ff128-ep500]:[d64_el3_dl3_ff128-ep1000]]),1,0) -> 0 | V12: =IF(H12=MIN(Tabelle4[[#This Row],[d32_el2_dl2_ff128-ep500]:[d64_el3_dl3_ff128-ep1000]]),1,0) -> 0 | W12: =IF(I12=MIN(Tabelle4[[#This Row],[d32_el2_dl2_ff128-ep500]:[d64_el3_dl3_ff128-ep1000]]),1,0) -> 0 | X12: =IF(J12=MIN(Tabelle4[[#This Row],[d32_el2_dl2_ff128-ep500]:[d64_el3_dl3_ff128-ep1000]]),1,0) -> 0 | Y12: =IF(K12=MIN(Tabelle4[[#This Row],[d32_el2_dl2_ff128-ep500]:[d64_el3_dl3_ff128-ep1000]]),1,0) -> 0 | Z12: =IF(L12=MIN(Tabelle4[[#This Row],[d32_el2_dl2_ff128-ep500]:[d64_el3_dl3_ff128-ep1000]]),1,0) -> 0 | AA12: =IF(M12=MIN(Tabelle4[[#This Row],[d32_el2_dl2_ff128-ep500]:[d64_el3_dl3_ff128-ep1000]]),1,0) -> 1
A13: 4 | B13: d64_el2_dl2_ff64-ep1000 | C13: ['wie frage vergleich'] | D13: 7 | E13: =D13+E6 -> 7 | G13: 12 | H13: {=INDEX($D$2:$D$701, (ROW()-ROW($G$2))*7 + (COLUMN()-COLUMN($G$2)) + 1)} -> 0 | I13: {=INDEX($D$2:$D$701, (ROW()-ROW($G$2))*7 + (COLUMN()-COLUMN($G$2)) + 1)} -> 3 | J13: {=INDEX($D$2:$D$701, (ROW()-ROW($G$2))*7 + (COLUMN()-COLUMN($G$2)) + 1)} -> 0 | K13: {=INDEX($D$2:$D$701, (ROW()-ROW($G$2))*7 + (COLUMN()-COLUMN($G$2)) + 1)} -> 0 | L13: {=INDEX($D$2:$D$701, (ROW()-ROW($G$2))*7 + (COLUMN()-COLUMN($G$2)) + 1)} -> 0 | M13: {=INDEX($D$2:$D$701, (ROW()-ROW($G$2))*7 + (COLUMN()-COLUMN($G$2)) + 1)} -> 0 | O13: =IF(H13=MAX(Tabelle4[[#This Row],[d32_el2_dl2_ff128-ep500]:[d64_el3_dl3_ff128-ep1000]]),1,0) -> 0 | P13: =IF(I13=MAX(Tabelle4[[#This Row],[d32_el2_dl2_ff128-ep500]:[d64_el3_dl3_ff128-ep1000]]),1,0) -> 1 | Q13: =IF(J13=MAX(Tabelle4[[#This Row],[d32_el2_dl2_ff128-ep500]:[d64_el3_dl3_ff128-ep1000]]),1,0) -> 0 | R13: =IF(K13=MAX(Tabelle4[[#This Row],[d32_el2_dl2_ff128-ep500]:[d64_el3_dl3_ff128-ep1000]]),1,0) -> 0 | S13: =IF(L13=MAX(Tabelle4[[#This Row],[d32_el2_dl2_ff128-ep500]:[d64_el3_dl3_ff128-ep1000]]),1,0) -> 0 | T13: =IF(M13=MAX(Tabelle4[[#This Row],[d32_el2_dl2_ff128-ep500]:[d64_el3_dl3_ff128-ep1000]]),1,0) -> 0 | V13: =IF(H13=MIN(Tabelle4[[#This Row],[d32_el2_dl2_ff128-ep500]:[d64_el3_dl3_ff128-ep1000]]),1,0) -> 1 | W13: =IF(I13=MIN(Tabelle4[[#This Row],[d32_el2_dl2_ff128-ep500]:[d64_el3_dl3_ff128-ep1000]]),1,0) -> 0 | X13: =IF(J13=MIN(Tabelle4[[#This Row],[d32_el2_dl2_ff128-ep500]:[d64_el3_dl3_ff128-ep1000]]),1,0) -> 1 | Y13: =IF(K13=MIN(Tabelle4[[#This Row],[d32_el2_dl2_ff128-ep500]:[d64_el3_dl3_ff128-ep1000]]),1,0) -> 1 | Z13: =IF(L13=MIN(Tabelle4[[#This Row],[d32_el2_dl2_ff128-ep500]:[d64_el3_dl3_ff128-ep1000]]),1,0) -> 1 | AA13: =IF(M13=MIN(Tabelle4[[#This Row],[d32_el2_dl2_ff128-ep500]:[d64_el3_dl3_ff128-ep1000]]),1,0) -> 1
A14: 5 | B14: d64_el2_dl2_ff128-ep1000 | C14: ['wie frage vergleich'] | D14: 7 | E14: =D14+E7 -> 8 | G14: 13 | H14: {=INDEX($D$2:$D$701, (ROW()-ROW($G$2))*7 + (COLUMN()-COLUMN($G$2)) + 1)} -> 10 | I14: {=INDEX($D$2:$D$701, (ROW()-ROW($G$2))*7 + (COLUMN()-COLUMN($G$2)) + 1)} -> 10 | J14: {=INDEX($D$2:$D$701, (ROW()-ROW($G$2))*7 + (COLUMN()-COLUMN($G$2)) + 1)} -> 9 | K14: {=INDEX($D$2:$D$701, (ROW()-ROW($G$2))*7 + (COLUMN()-COLUMN($G$2)) + 1)} -> 3 | L14: {=INDEX($D$2:$D$701, (ROW()-ROW($G$2))*7 + (COLUMN()-COLUMN($G$2)) + 1)} -> 9 | M14: {=INDEX($D$2:$D$701, (ROW()-ROW($G$2))*7 + (COLUMN()-COLUMN($G$2)) + 1)} -> 9 | O14: =IF(H14=MAX(Tabelle4[[#This Row],[d32_el2_dl2_ff128-ep500]:[d64_el3_dl3_ff128-ep1000]]),1,0) -> 1 | P14: =IF(I14=MAX(Tabelle4[[#This Row],[d32_el2_dl2_ff128-ep500]:[d64_el3_dl3_ff128-ep1000]]),1,0) -> 1 | Q14: =IF(J14=MAX(Tabelle4[[#This Row],[d32_el2_dl2_ff128-ep500]:[d64_el3_dl3_ff128-ep1000]]),1,0) -> 0 | R14: =IF(K14=MAX(Tabelle4[[#This Row],[d32_el2_dl2_ff128-ep500]:[d64_el3_dl3_ff128-ep1000]]),1,0) -> 0 | S14: =IF(L14=MAX(Tabelle4[[#This Row],[d32_el2_dl2_ff128-ep500]:[d64_el3_dl3_ff128-ep1000]]),1,0) -> 0 | T14: =IF(M14=MAX(Tabelle4[[#This Row],[d32_el2_dl2_ff128-ep500]:[d64_el3_dl3_ff128-ep1000]]),1,0) -> 0 | V14: =IF(H14=MIN(Tabelle4[[#This Row],[d32_el2_dl2_ff128-ep500]:[d64_el3_dl3_ff128-ep1000]]),1,0) -> 0 | W14: =IF(I14=MIN(Tabelle4[[#This Row],[d32_el2_dl2_ff128-ep500]:[d64_el3_dl3_ff128-ep1000]]),1,0) -> 0 | X14: =IF(J14=MIN(Tabelle4[[#This Row],[d32_el2_dl2_ff128-ep500]:[d64_el3_dl3_ff128-ep1000]]),1,0) -> 0 | Y14: =IF(K14=MIN(Tabelle4[[#This Row],[d32_el2_dl2_ff128-ep500]:[d64_el3_dl3_ff128-ep1000]]),1,0) -> 1 | Z14: =IF(L14=MIN(Tabelle4[[#This Row],[d32_el2_dl2_ff128-ep500]:[d64_el3_dl3_ff128-ep1000]]),1,0) -> 0 | AA14: =IF(M14=MIN(Tabelle4[[#This Row],[d32_el2_dl2_ff128-ep500]:[d64_el3_dl3_ff128-ep1000]]),1,0) -> 0
A15: 6 | B15: d64_el3_dl3_ff128-ep1000 | C15: ['wie frage vergleich'] | D15: 7 | E15: =D15+E8 -> 7 | G15: 14 | H15: {=INDEX($D$2:$D$701, (ROW()-ROW($G$2))*7 + (COLUMN()-COLUMN($G$2)) + 1)} -> 8 | I15: {=INDEX($D$2:$D$701, (ROW()-ROW($G$2))*7 + (COLUMN()-COLUMN($G$2)) + 1)} -> 10 | J15: {=INDEX($D$2:$D$701, (ROW()-ROW($G$2))*7 + (COLUMN()-COLUMN($G$2)) + 1)} -> 5 | K15: {=INDEX($D$2:$D$701, (ROW()-ROW($G$2))*7 + (COLUMN()-COLUMN($G$2)) + 1)} -> 6 | L15: {=INDEX($D$2:$D$701, (ROW()-ROW($G$2))*7 + (COLUMN()-COLUMN($G$2)) + 1)} -> 0 | M15: {=INDEX($D$2:$D$701, (ROW()-ROW($G$2))*7 + (COLUMN()-COLUMN($G$2)) + 1)} -> 2 | O15: =IF(H15=MAX(Tabelle4[[#This Row],[d32_el2_dl2_ff128-ep500]:[d64_el3_dl3_ff128-ep1000]]),1,0) -> 0 | P15: =IF(I15=MAX(Tabelle4[[#This Row],[d32_el2_dl2_ff128-ep500]:[d64_el3_dl3_ff128-ep1000]]),1,0) -> 1 | Q15: =IF(J15=MAX(Tabelle4[[#This Row],[d32_el2_dl2_ff128-ep500]:[d64_el3_dl3_ff128-ep1000]]),1,0) -> 0 | R15: =IF(K15=MAX(Tabelle4[[#This Row],[d32_el2_dl2_ff128-ep500]:[d64_el3_dl3_ff128-ep1000]]),1,0) -> 0 | S15: =IF(L15=MAX(Tabelle4[[#This Row],[d32_el2_dl2_ff128-ep500]:[d64_el3_dl3_ff128-ep1000]]),1,0) -> 0 | T15: =IF(M15=MAX(Tabelle4[[#This Row],[d32_el2_dl2_ff128-ep500]:[d64_el3_dl3_ff128-ep1000]]),1,0) -> 0 | V15: =IF(H15=MIN(Tabelle4[[#This Row],[d32_el2_dl2_ff128-ep500]:[d64_el3_dl3_ff128-ep1000]]),1,0) -> 0 | W15: =IF(I15=MIN(Tabelle4[[#This Row],[d32_el2_dl2_ff128-ep500]:[d64_el3_dl3_ff128-ep1000]]),1,0) -> 0 | X15: =IF(J15=MIN(Tabelle4[[#This Row],[d32_el2_dl2_ff128-ep500]:[d64_el3_dl3_ff128-ep1000]]),1,0) -> 0 | Y15: =IF(K15=MIN(Tabelle4[[#This Row],[d32_el2_dl2_ff128-ep500]:[d64_el3_dl3_ff128-ep1000]]),1,0) -> 0 | Z15: =IF(L15=MIN(Tabelle4[[#This Row],[d32_el2_dl2_ff128-ep500]:[d64_el3_dl3_ff128-ep1000]]),1,0) -> 1 | AA15: =IF(M15=MIN(Tabelle4[[#This Row],[d32_el2_dl2_ff128-ep500]:[d64_el3_dl3_ff128-ep1000]]),1,0) -> 0
A16: 0 | B16: 3 | C16: Hast du gut geschlafen? | E16: =D16+E9 -> 0 | G16: 15 | H16: {=INDEX($D$2:$D$701, (ROW()-ROW($G$2))*7 + (COLUMN()-COLUMN($G$2)) + 1)} -> 1 | I16: {=INDEX($D$2:$D$701, (ROW()-ROW($G$2))*7 + (COLUMN()-COLUMN($G$2)) + 1)} -> 2 | J16: {=INDEX($D$2:$D$701, (ROW()-ROW($G$2))*7 + (COLUMN()-COLUMN($G$2)) + 1)} -> 4 | K16: {=INDEX($D$2:$D$701, (ROW()-ROW($G$2))*7 + (COLUMN()-COLUMN($G$2)) + 1)} -> 4 | L16: {=INDEX($D$2:$D$701, (ROW()-ROW($G$2))*7 + (COLUMN()-COLUMN($G$2)) + 1)} -> 2 | M16: {=INDEX($D$2:$D$701, (ROW()-ROW($G$2))*7 + (COLUMN()-COLUMN($G$2)) + 1)} -> 4 | O16: =IF(H16=MAX(Tabelle4[[#This Row],[d32_el2_dl2_ff128-ep500]:[d64_el3_dl3_ff128-ep1000]]),1,0) -> 0 | P16: =IF(I16=MAX(Tabelle4[[#This Row],[d32_el2_dl2_ff128-ep500]:[d64_el3_dl3_ff128-ep1000]]),1,0) -> 0 | Q16: =IF(J16=MAX(Tabelle4[[#This Row],[d32_el2_dl2_ff128-ep500]:[d64_el3_dl3_ff128-ep1000]]),1,0) -> 1 | R16: =IF(K16=MAX(Tabelle4[[#This Row],[d32_el2_dl2_ff128-ep500]:[d64_el3_dl3_ff128-ep1000]]),1,0) -> 1 | S16: =IF(L16=MAX(Tabelle4[[#This Row],[d32_el2_dl2_ff128-ep500]:[d64_el3_dl3_ff128-ep1000]]),1,0) -> 0 | T16: =IF(M16=MAX(Tabelle4[[#This Row],[d32_el2_dl2_ff128-ep500]:[d64_el3_dl3_ff128-ep1000]]),1,0) -> 1 | V16: =IF(H16=MIN(Tabelle4[[#This Row],[d32_el2_dl2_ff128-ep500]:[d64_el3_dl3_ff128-ep1000]]),1,0) -> 1 | W16: =IF(I16=MIN(Tabelle4[[#This Row],[d32_el2_dl2_ff128-ep500]:[d64_el3_dl3_ff128-ep1000]]),1,0) -> 0 | X16: =IF(J16=MIN(Tabelle4[[#This Row],[d32_el2_dl2_ff128-ep500]:[d64_el3_dl3_ff128-ep1000]]),1,0) -> 0 | Y16: =IF(K16=MIN(Tabelle4[[#This Row],[d32_el2_dl2_ff128-ep500]:[d64_el3_dl3_ff128-ep1000]]),1,0) -> 0 | Z16: =IF(L16=MIN(Tabelle4[[#This Row],[d32_el2_dl2_ff128-ep500]:[d64_el3_dl3_ff128-ep1000]]),1,0) -> 0 | AA16: =IF(M16=MIN(Tabelle4[[#This Row],[d32_el2_dl2_ff128-ep500]:[d64_el3_dl3_ff128-ep1000]]),1,0) -> 0
A17: 1 | B17: d32_el2_dl2_ff128-ep500 | C17: ['schlafen', 'schlafen', 'schlafen', 'schlafen'] | D17: 2 | E17: =D17+E10 -> 14 | G17: 16 | H17: {=INDEX($D$2:$D$701, (ROW()-ROW($G$2))*7 + (COLUMN()-COLUMN($G$2)) + 1)} -> 1 | I17: {=INDEX($D$2:$D$701, (ROW()-ROW($G$2))*7 + (COLUMN()-COLUMN($G$2)) + 1)} -> 4 | J17: {=INDEX($D$2:$D$701, (ROW()-ROW($G$2))*7 + (COLUMN()-COLUMN($G$2)) + 1)} -> 0 | K17: {=INDEX($D$2:$D$701, (ROW()-ROW($G$2))*7 + (COLUMN()-COLUMN($G$2)) + 1)} -> 0 | L17: {=INDEX($D$2:$D$701, (ROW()-ROW($G$2))*7 + (COLUMN()-COLUMN($G$2)) + 1)} -> 0 | M17: {=INDEX($D$2:$D$701, (ROW()-ROW($G$2))*7 + (COLUMN()-COLUMN($G$2)) + 1)} -> 1 | O17: =IF(H17=MAX(Tabelle4[[#This Row],[d32_el2_dl2_ff128-ep500]:[d64_el3_dl3_ff128-ep1000]]),1,0) -> 0 | P17: =IF(I17=MAX(Tabelle4[[#This Row],[d32_el2_dl2_ff128-ep500]:[d64_el3_dl3_ff128-ep1000]]),1,0) -> 1 | Q17: =IF(J17=MAX(Tabelle4[[#This Row],[d32_el2_dl2_ff128-ep500]:[d64_el3_dl3_ff128-ep1000]]),1,0) -> 0 | R17: =IF(K17=MAX(Tabelle4[[#This Row],[d32_el2_dl2_ff128-ep500]:[d64_el3_dl3_ff128-ep1000]]),1,0) -> 0 | S17: =IF(L17=MAX(Tabelle4[[#This Row],[d32_el2_dl2_ff128-ep500]:[d64_el3_dl3_ff128-ep1000]]),1,0) -> 0 | T17: =IF(M17=MAX(Tabelle4[[#This Row],[d32_el2_dl2_ff128-ep500]:[d64_el3_dl3_ff128-ep1000]]),1,0) -> 0 | V17: =IF(H17=MIN(Tabelle4[[#This Row],[d32_el2_dl2_ff128-ep500]:[d64_el3_dl3_ff128-ep1000]]),1,0) -> 0 | W17: =IF(I17=MIN(Tabelle4[[#This Row],[d32_el2_dl2_ff128-ep500]:[d64_el3_dl3_ff128-ep1000]]),1,0) -> 0 | X17: =IF(J17=MIN(Tabelle4[[#This Row],[d32_el2_dl2_ff128-ep500]:[d64_el3_dl3_ff128-ep1000]]),1,0) -> 1 | Y17: =IF(K17=MIN(Tabelle4[[#This Row],[d32_el2_dl2_ff128-ep500]:[d64_el3_dl3_ff128-ep1000]]),1,0) -> 1 | Z17: =IF(L17=MIN(Tabelle4[[#This Row],[d32_el2_dl2_ff128-ep500]:[d64_el3_dl3_ff128-ep1000]]),1,0) -> 1 | AA17: =IF(M17=MIN(Tabelle4[[#This Row],[d32_el2_dl2_ff128-ep500]:[d64_el3_dl3_ff128-ep1000]]),1,0) -> 0
A18: 2 | B18: d64_el1_dl1_ff64-ep1000 | C18: ['schlafen', 'du', 'schlafen', 'du', 'schlafen', 'du', 'schlafen', 'du'] | D18: 4 | E18: =D18+E11 -> 12 | G18: 17 | H18: {=INDEX($D$2:$D$701, (ROW()-ROW($G$2))*7 + (COLUMN()-COLUMN($G$2)) + 1)} -> 0 | I18: {=INDEX($D$2:$D$701, (ROW()-ROW($G$2))*7 + (COLUMN()-COLUMN($G$2)) + 1)} -> 9 | J18: {=INDEX($D$2:$D$701, (ROW()-ROW($G$2))*7 + (COLUMN()-COLUMN($G$2)) + 1)} -> 0 | K18: {=INDEX($D$2:$D$701, (ROW()-ROW($G$2))*7 + (COLUMN()-COLUMN($G$2)) + 1)} -> 0 | L18: {=INDEX($D$2:$D$701, (ROW()-ROW($G$2))*7 + (COLUMN()-COLUMN($G$2)) + 1)} -> 5 | M18: {=INDEX($D$2:$D$701, (ROW()-ROW($G$2))*7 + (COLUMN()-COLUMN($G$2)) + 1)} -> 0 | O18: =IF(H18=MAX(Tabelle4[[#This Row],[d32_el2_dl2_ff128-ep500]:[d64_el3_dl3_ff128-ep1000]]),1,0) -> 0 | P18: =IF(I18=MAX(Tabelle4[[#This Row],[d32_el2_dl2_ff128-ep500]:[d64_el3_dl3_ff128-ep1000]]),1,0) -> 1 | Q18: =IF(J18=MAX(Tabelle4[[#This Row],[d32_el2_dl2_ff128-ep500]:[d64_el3_dl3_ff128-ep1000]]),1,0) -> 0 | R18: =IF(K18=MAX(Tabelle4[[#This Row],[d32_el2_dl2_ff128-ep500]:[d64_el3_dl3_ff128-ep1000]]),1,0) -> 0 | S18: =IF(L18=MAX(Tabelle4[[#This Row],[d32_el2_dl2_ff128-ep500]:[d64_el3_dl3_ff128-ep1000]]),1,0) -> 0 | T18: =IF(M18=MAX(Tabelle4[[#This Row],[d32_el2_dl2_ff128-ep500]:[d64_el3_dl3_ff128-ep1000]]),1,0) -> 0 | V18: =IF(H18=MIN(Tabelle4[[#This Row],[d32_el2_dl2_ff128-ep500]:[d64_el3_dl3_ff128-ep1000]]),1,0) -> 1 | W18: =IF(I18=MIN(Tabelle4[[#This Row],[d32_el2_dl2_ff128-ep500]:[d64_el3_dl3_ff128-ep1000]]),1,0) -> 0 | X18: =IF(J18=MIN(Tabelle4[[#This Row],[d32_el2_dl2_ff128-ep500]:[d64_el3_dl3_ff128-ep1000]]),1,0) -> 1 | Y18: =IF(K18=MIN(Tabelle4[[#This Row],[d32_el2_dl2_ff128-ep500]:[d64_el3_dl3_ff128-ep1000]]),1,0) -> 1 | Z18: =IF(L18=MIN(Tabelle4[[#This Row],[d32_el2_dl2_ff128-ep500]:[d64_el3_dl3_ff128-ep1000]]),1,0) -> 0 | AA18: =IF(M18=MIN(Tabelle4[[#This Row],[d32_el2_dl2_ff128-ep500]:[d64_el3_dl3_ff128-ep1000]]),1,0) -> 1
A19: 3 | B19: d64_el2_dl2_ff64-ep500 | C19: ['schlafen', 'gut'] | D19: 10 | E19: =D19+E12 -> 17 | G19: 18 | H19: {=INDEX($D$2:$D$701, (ROW()-ROW($G$2))*7 + (COLUMN()-COLUMN($G$2)) + 1)} -> 8 | I19: {=INDEX($D$2:$D$701, (ROW()-ROW($G$2))*7 + (COLUMN()-COLUMN($G$2)) + 1)} -> 10 | J19: {=INDEX($D$2:$D$701, (ROW()-ROW($G$2))*7 + (COLUMN()-COLUMN($G$2)) + 1)} -> 10 | K19: {=INDEX($D$2:$D$701, (ROW()-ROW($G$2))*7 + (COLUMN()-COLUMN($G$2)) + 1)} -> 8 | L19: {=INDEX($D$2:$D$701, (ROW()-ROW($G$2))*7 + (COLUMN()-COLUMN($G$2)) + 1)} -> 10 | M19: {=INDEX($D$2:$D$701, (ROW()-ROW($G$2))*7 + (COLUMN()-COLUMN($G$2)) + 1)} -> 10 | O19: =IF(H19=MAX(Tabelle4[[#This Row],[d32_el2_dl2_ff128-ep500]:[d64_el3_dl3_ff128-ep1000]]),1,0) -> 0 | P19: =IF(I19=MAX(Tabelle4[[#This Row],[d32_el2_dl2_ff128-ep500]:[d64_el3_dl3_ff128-ep1000]]),1,0) -> 1 | Q19: =IF(J19=MAX(Tabelle4[[#This Row],[d32_el2_dl2_ff128-ep500]:[d64_el3_dl3_ff128-ep1000]]),1,0) -> 1 | R19: =IF(K19=MAX(Tabelle4[[#This Row],[d32_el2_dl2_ff128-ep500]:[d64_el3_dl3_ff128-ep1000]]),1,0) -> 0 | S19: =IF(L19=MAX(Tabelle4[[#This Row],[d32_el2_dl2_ff128-ep500]:[d64_el3_dl3_ff128-ep1000]]),1,0) -> 1 | T19: =IF(M19=MAX(Tabelle4[[#This Row],[d32_el2_dl2_ff128-ep500]:[d64_el3_dl3_ff128-ep1000]]),1,0) -> 1 | V19: =IF(H19=MIN(Tabelle4[[#This Row],[d32_el2_dl2_ff128-ep500]:[d64_el3_dl3_ff128-ep1000]]),1,0) -> 1 | W19: =IF(I19=MIN(Tabelle4[[#This Row],[d32_el2_dl2_ff128-ep500]:[d64_el3_dl3_ff128-ep1000]]),1,0) -> 0 | X19: =IF(J19=MIN(Tabelle4[[#This Row],[d32_el2_dl2_ff128-ep500]:[d64_el3_dl3_ff128-ep1000]]),1,0) -> 0 | Y19: =IF(K19=MIN(Tabelle4[[#This Row],[d32_el2_dl2_ff128-ep500]:[d64_el3_dl3_ff128-ep1000]]),1,0) -> 1 | Z19: =IF(L19=MIN(Tabelle4[[#This Row],[d32_el2_dl2_ff128-ep500]:[d64_el3_dl3_ff128-ep1000]]),1,0) -> 0 | AA19: =IF(M19=MIN(Tabelle4[[#This Row],[d32_el2_dl2_ff128-ep500]:[d64_el3_dl3_ff128-ep1000]]),1,0) -> 0
A20: 4 | B20: d64_el2_dl2_ff64-ep1000 | C20: ['schlafen', 'gut'] | D20: 10 | E20: =D20+E13 -> 17 | G20: 19 | H20: {=INDEX($D$2:$D$701, (ROW()-ROW($G$2))*7 + (COLUMN()-COLUMN($G$2)) + 1)} -> 2 | I20: {=INDEX($D$2:$D$701, (ROW()-ROW($G$2))*7 + (COLUMN()-COLUMN($G$2)) + 1)} -> 0 | J20: {=INDEX($D$2:$D$701, (ROW()-ROW($G$2))*7 + (COLUMN()-COLUMN($G$2)) + 1)} -> 3 | K20: {=INDEX($D$2:$D$701, (ROW()-ROW($G$2))*7 + (COLUMN()-COLUMN($G$2)) + 1)} -> 1 | L20: {=INDEX($D$2:$D$701, (ROW()-ROW($G$2))*7 + (COLUMN()-COLUMN($G$2)) + 1)} -> 0 | M20: {=INDEX($D$2:$D$701, (ROW()-ROW($G$2))*7 + (COLUMN()-COLUMN($G$2)) + 1)} -> 0 | O20: =IF(H20=MAX(Tabelle4[[#This Row],[d32_el2_dl2_ff128-ep500]:[d64_el3_dl3_ff128-ep1000]]),1,0) -> 0 | P20: =IF(I20=MAX(Tabelle4[[#This Row],[d32_el2_dl2_ff128-ep500]:[d64_el3_dl3_ff128-ep1000]]),1,0) -> 0 | Q20: =IF(J20=MAX(Tabelle4[[#This Row],[d32_el2_dl2_ff128-ep500]:[d64_el3_dl3_ff128-ep1000]]),1,0) -> 1 | R20: =IF(K20=MAX(Tabelle4[[#This Row],[d32_el2_dl2_ff128-ep500]:[d64_el3_dl3_ff128-ep1000]]),1,0) -> 0 | S20: =IF(L20=MAX(Tabelle4[[#This Row],[d32_el2_dl2_ff128-ep500]:[d64_el3_dl3_ff128-ep1000]]),1,0) -> 0 | T20: =IF(M20=MAX(Tabelle4[[#This Row],[d32_el2_dl2_ff128-ep500]:[d64_el3_dl3_ff128-ep1000]]),1,0) -> 0 | V20: =IF(H20=MIN(Tabelle4[[#This Row],[d32_el2_dl2_ff128-ep500]:[d64_el3_dl3_ff128-ep1000]]),1,0) -> 0 | W20: =IF(I20=MIN(Tabelle4[[#This Row],[d32_el2_dl2_ff128-ep500]:[d64_el3_dl3_ff128-ep1000]]),1,0) -> 1 | X20: =IF(J20=MIN(Tabelle4[[#This Row],[d32_el2_dl2_ff128-ep500]:[d64_el3_dl3_ff128-ep1000]]),1,0) -> 0 | Y20: =IF(K20=MIN(Tabelle4[[#This Row],[d32_el2_dl2_ff128-ep500]:[d64_el3_dl3_ff128-ep1000]]),1,0) -> 0 | Z20: =IF(L20=MIN(Tabelle4[[#This Row],[d32_el2_dl2_ff128-ep500]:[d64_el3_dl3_ff128-ep1000]]),1,0) -> 1 | AA20: =IF(M20=MIN(Tabelle4[[#This Row],[d32_el2_dl2_ff128-ep500]:[d64_el3_dl3_ff128-ep1000]]),1,0) -> 1
A21: 5 | B21: d64_el2_dl2_ff128-ep1000 | C21: ['schlafen', 'gut', 'schlafen'] | D21: 9 | E21: =D21+E14 -> 17 | G21: 20 | H21: {=INDEX($D$2:$D$701, (ROW()-ROW($G$2))*7 + (COLUMN()-COLUMN($G$2)) + 1)} -> 8 | I21: {=INDEX($D$2:$D$701, (ROW()-ROW($G$2))*7 + (COLUMN()-COLUMN($G$2)) + 1)} -> 5 | J21: {=INDEX($D$2:$D$701, (ROW()-ROW($G$2))*7 + (COLUMN()-COLUMN($G$2)) + 1)} -> 6 | K21: {=INDEX($D$2:$D$701, (ROW()-ROW($G$2))*7 + (COLUMN()-COLUMN($G$2)) + 1)} -> 10 | L21: {=INDEX($D$2:$D$701, (ROW()-ROW($G$2))*7 + (COLUMN()-COLUMN($G$2)) + 1)} -> 5 | M21: {=INDEX($D$2:$D$701, (ROW()-ROW($G$2))*7 + (COLUMN()-COLUMN($G$2)) + 1)} -> 5 | O21: =IF(H21=MAX(Tabelle4[[#This Row],[d32_el2_dl2_ff128-ep500]:[d64_el3_dl3_ff128-ep1000]]),1,0) -> 0 | P21: =IF(I21=MAX(Tabelle4[[#This Row],[d32_el2_dl2_ff128-ep500]:[d64_el3_dl3_ff128-ep1000]]),1,0) -> 0 | Q21: =IF(J21=MAX(Tabelle4[[#This Row],[d32_el2_dl2_ff128-ep500]:[d64_el3_dl3_ff128-ep1000]]),1,0) -> 0 | R21: =IF(K21=MAX(Tabelle4[[#This Row],[d32_el2_dl2_ff128-ep500]:[d64_el3_dl3_ff128-ep1000]]),1,0) -> 1 | S21: =IF(L21=MAX(Tabelle4[[#This Row],[d32_el2_dl2_ff128-ep500]:[d64_el3_dl3_ff128-ep1000]]),1,0) -> 0 | T21: =IF(M21=MAX(Tabelle4[[#This Row],[d32_el2_dl2_ff128-ep500]:[d64_el3_dl3_ff128-ep1000]]),1,0) -> 0 | V21: =IF(H21=MIN(Tabelle4[[#This Row],[d32_el2_dl2_ff128-ep500]:[d64_el3_dl3_ff128-ep1000]]),1,0) -> 0 | W21: =IF(I21=MIN(Tabelle4[[#This Row],[d32_el2_dl2_ff128-ep500]:[d64_el3_dl3_ff128-ep1000]]),1,0) -> 1 | X21: =IF(J21=MIN(Tabelle4[[#This Row],[d32_el2_dl2_ff128-ep500]:[d64_el3_dl3_ff128-ep1000]]),1,0) -> 0 | Y21: =IF(K21=MIN(Tabelle4[[#This Row],[d32_el2_dl2_ff128-ep500]:[d64_el3_dl3_ff128-ep1000]]),1,0) -> 0 | Z21: =IF(L21=MIN(Tabelle4[[#This Row],[d32_el2_dl2_ff128-ep500]:[d64_el3_dl3_ff128-ep1000]]),1,0) -> 1 | AA21: =IF(M21=MIN(Tabelle4[[#This Row],[d32_el2_dl2_ff128-ep500]:[d64_el3_dl3_ff128-ep1000]]),1,0) -> 1
A22: 6 | B22: d64_el3_dl3_ff128-ep1000 | C22: ['du', 'schlafen', 'index'] | D22: 8 | E22: =D22+E15 -> 15 | G22: 21 | H22: {=INDEX($D$2:$D$701, (ROW()-ROW($G$2))*7 + (COLUMN()-COLUMN($G$2)) + 1)} -> 9 | I22: {=INDEX($D$2:$D$701, (ROW()-ROW($G$2))*7 + (COLUMN()-COLUMN($G$2)) + 1)} -> 9 | J22: {=INDEX($D$2:$D$701, (ROW()-ROW($G$2))*7 + (COLUMN()-COLUMN($G$2)) + 1)} -> 9 | K22: {=INDEX($D$2:$D$701, (ROW()-ROW($G$2))*7 + (COLUMN()-COLUMN($G$2)) + 1)} -> 9 | L22: {=INDEX($D$2:$D$701, (ROW()-ROW($G$2))*7 + (COLUMN()-COLUMN($G$2)) + 1)} -> 9 | M22: {=INDEX($D$2:$D$701, (ROW()-ROW($G$2))*7 + (COLUMN()-COLUMN($G$2)) + 1)} -> 9 | O22: =IF(H22=MAX(Tabelle4[[#This Row],[d32_el2_dl2_ff128-ep500]:[d64_el3_dl3_ff128-ep1000]]),1,0) -> 1 | P22: =IF(I22=MAX(Tabelle4[[#This Row],[d32_el2_dl2_ff128-ep500]:[d64_el3_dl3_ff128-ep1000]]),1,0) -> 1 | Q22: =IF(J22=MAX(Tabelle4[[#This Row],[d32_el2_dl2_ff128-ep500]:[d64_el3_dl3_ff128-ep1000]]),1,0) -> 1 | R22: =IF(K22=MAX(Tabelle4[[#This Row],[d32_el2_dl2_ff128-ep500]:[d64_el3_dl3_ff128-ep1000]]),1,0) -> 1 | S22: =IF(L22=MAX(Tabelle4[[#This Row],[d32_el2_dl2_ff128-ep500]:[d64_el3_dl3_ff128-ep1000]]),1,0) -> 1 | T22: =IF(M22=MAX(Tabelle4[[#This Row],[d32_el2_dl2_ff128-ep500]:[d64_el3_dl3_ff128-ep1000]]),1,0) -> 1 | V22: =IF(H22=MIN(Tabelle4[[#This Row],[d32_el2_dl2_ff128-ep500]:[d64_el3_dl3_ff128-ep1000]]),1,0) -> 1 | W22: =IF(I22=MIN(Tabelle4[[#This Row],[d32_el2_dl2_ff128-ep500]:[d64_el3_dl3_ff128-ep1000]]),1,0) -> 1 | X22: =IF(J22=MIN(Tabelle4[[#This Row],[d32_el2_dl2_ff128-ep500]:[d64_el3_dl3_ff128-ep1000]]),1,0) -> 1 | Y22: =IF(K22=MIN(Tabelle4[[#This Row],[d32_el2_dl2_ff128-ep500]:[d64_el3_dl3_ff128-ep1000]]),1,0) -> 1 | Z22: =IF(L22=MIN(Tabelle4[[#This Row],[d32_el2_dl2_ff128-ep500]:[d64_el3_dl3_ff128-ep1000]]),1,0) -> 1 | AA22: =IF(M22=MIN(Tabelle4[[#This Row],[d32_el2_dl2_ff128-ep500]:[d64_el3_dl3_ff128-ep1000]]),1,0) -> 1
A23: 0 | B23: 4 | C23: Kannst du mir bitte helfen? | E23: =D23+E16 -> 0 | G23: 22 | H23: {=INDEX($D$2:$D$701, (ROW()-ROW($G$2))*7 + (COLUMN()-COLUMN($G$2)) + 1)} -> 10 | I23: {=INDEX($D$2:$D$701, (ROW()-ROW($G$2))*7 + (COLUMN()-COLUMN($G$2)) + 1)} -> 10 | J23: {=INDEX($D$2:$D$701, (ROW()-ROW($G$2))*7 + (COLUMN()-COLUMN($G$2)) + 1)} -> 10 | K23: {=INDEX($D$2:$D$701, (ROW()-ROW($G$2))*7 + (COLUMN()-COLUMN($G$2)) + 1)} -> 5 | L23: {=INDEX($D$2:$D$701, (ROW()-ROW($G$2))*7 + (COLUMN()-COLUMN($G$2)) + 1)} -> 9 | M23: {=INDEX($D$2:$D$701, (ROW()-ROW($G$2))*7 + (COLUMN()-COLUMN($G$2)) + 1)} -> 4 | O23: =IF(H23=MAX(Tabelle4[[#This Row],[d32_el2_dl2_ff128-ep500]:[d64_el3_dl3_ff128-ep1000]]),1,0) -> 1 | P23: =IF(I23=MAX(Tabelle4[[#This Row],[d32_el2_dl2_ff128-ep500]:[d64_el3_dl3_ff128-ep1000]]),1,0) -> 1 | Q23: =IF(J23=MAX(Tabelle4[[#This Row],[d32_el2_dl2_ff128-ep500]:[d64_el3_dl3_ff128-ep1000]]),1,0) -> 1 | R23: =IF(K23=MAX(Tabelle4[[#This Row],[d32_el2_dl2_ff128-ep500]:[d64_el3_dl3_ff128-ep1000]]),1,0) -> 0 | S23: =IF(L23=MAX(Tabelle4[[#This Row],[d32_el2_dl2_ff128-ep500]:[d64_el3_dl3_ff128-ep1000]]),1,0) -> 0 | T23: =IF(M23=MAX(Tabelle4[[#This Row],[d32_el2_dl2_ff128-ep500]:[d64_el3_dl3_ff128-ep1000]]),1,0) -> 0 | V23: =IF(H23=MIN(Tabelle4[[#This Row],[d32_el2_dl2_ff128-ep500]:[d64_el3_dl3_ff128-ep1000]]),1,0) -> 0 | W23: =IF(I23=MIN(Tabelle4[[#This Row],[d32_el2_dl2_ff128-ep500]:[d64_el3_dl3_ff128-ep1000]]),1,0) -> 0 | X23: =IF(J23=MIN(Tabelle4[[#This Row],[d32_el2_dl2_ff128-ep500]:[d64_el3_dl3_ff128-ep1000]]),1,0) -> 0 | Y23: =IF(K23=MIN(Tabelle4[[#This Row],[d32_el2_dl2_ff128-ep500]:[d64_el3_dl3_ff128-ep1000]]),1,0) -> 0 | Z23: =IF(L23=MIN(Tabelle4[[#This Row],[d32_el2_dl2_ff128-ep500]:[d64_el3_dl3_ff128-ep1000]]),1,0) -> 0 | AA23: =IF(M23=MIN(Tabelle4[[#This Row],[d32_el2_dl2_ff128-ep500]:[d64_el3_dl3_ff128-ep1000]]),1,0) -> 1
A24: 1 | B24: d32_el2_dl2_ff128-ep500 | C24: ['bitte', 'helfen'] | D24: 10 | E24: =D24+E17 -> 24 | G24: 23 | H24: {=INDEX($D$2:$D$701, (ROW()-ROW($G$2))*7 + (COLUMN()-COLUMN($G$2)) + 1)} -> 4 | I24: {=INDEX($D$2:$D$701, (ROW()-ROW($G$2))*7 + (COLUMN()-COLUMN($G$2)) + 1)} -> 0 | J24: {=INDEX($D$2:$D$701, (ROW()-ROW($G$2))*7 + (COLUMN()-COLUMN($G$2)) + 1)} -> 0 | K24: {=INDEX($D$2:$D$701, (ROW()-ROW($G$2))*7 + (COLUMN()-COLUMN($G$2)) + 1)} -> 0 | L24: {=INDEX($D$2:$D$701, (ROW()-ROW($G$2))*7 + (COLUMN()-COLUMN($G$2)) + 1)} -> 0 | M24: {=INDEX($D$2:$D$701, (ROW()-ROW($G$2))*7 + (COLUMN()-COLUMN($G$2)) + 1)} -> 0 | O24: =IF(H24=MAX(Tabelle4[[#This Row],[d32_el2_dl2_ff128-ep500]:[d64_el3_dl3_ff128-ep1000]]),1,0) -> 1 | P24: =IF(I24=MAX(Tabelle4[[#This Row],[d32_el2_dl2_ff128-ep500]:[d64_el3_dl3_ff128-ep1000]]),1,0) -> 0 | Q24: =IF(J24=MAX(Tabelle4[[#This Row],[d32_el2_dl2_ff128-ep500]:[d64_el3_dl3_ff128-ep1000]]),1,0) -> 0 | R24: =IF(K24=MAX(Tabelle4[[#This Row],[d32_el2_dl2_ff128-ep500]:[d64_el3_dl3_ff128-ep1000]]),1,0) -> 0 | S24: =IF(L24=MAX(Tabelle4[[#This Row],[d32_el2_dl2_ff128-ep500]:[d64_el3_dl3_ff128-ep1000]]),1,0) -> 0 | T24: =IF(M24=MAX(Tabelle4[[#This Row],[d32_el2_dl2_ff128-ep500]:[d64_el3_dl3_ff128-ep1000]]),1,0) -> 0 | V24: =IF(H24=MIN(Tabelle4[[#This Row],[d32_el2_dl2_ff128-ep500]:[d64_el3_dl3_ff128-ep1000]]),1,0) -> 0 | W24: =IF(I24=MIN(Tabelle4[[#This Row],[d32_el2_dl2_ff128-ep500]:[d64_el3_dl3_ff128-ep1000]]),1,0) -> 1 | X24: =IF(J24=MIN(Tabelle4[[#This Row],[d32_el2_dl2_ff128-ep500]:[d64_el3_dl3_ff128-ep1000]]),1,0) -> 1 | Y24: =IF(K24=MIN(Tabelle4[[#This Row],[d32_el2_dl2_ff128-ep500]:[d64_el3_dl3_ff128-ep1000]]),1,0) -> 1 | Z24: =IF(L24=MIN(Tabelle4[[#This Row],[d32_el2_dl2_ff128-ep500]:[d64_el3_dl3_ff128-ep1000]]),1,0) -> 1 | AA24: =IF(M24=MIN(Tabelle4[[#This Row],[d32_el2_dl2_ff128-ep500]:[d64_el3_dl3_ff128-ep1000]]),1,0) -> 1
A25: 2 | B25: d64_el1_dl1_ff64-ep1000 | C25: ['helfen', 'du', 'helfen', 'weg verlieren'] | D25: 6 | E25: =D25+E18 -> 18 | G25: 24 | H25: {=INDEX($D$2:$D$701, (ROW()-ROW($G$2))*7 + (COLUMN()-COLUMN($G$2)) + 1)} -> 0 | I25: {=INDEX($D$2:$D$701, (ROW()-ROW($G$2))*7 + (COLUMN()-COLUMN($G$2)) + 1)} -> 5 | J25: {=INDEX($D$2:$D$701, (ROW()-ROW($G$2))*7 + (COLUMN()-COLUMN($G$2)) + 1)} -> 1 | K25: {=INDEX($D$2:$D$701, (ROW()-ROW($G$2))*7 + (COLUMN()-COLUMN($G$2)) + 1)} -> 1 | L25: {=INDEX($D$2:$D$701, (ROW()-ROW($G$2))*7 + (COLUMN()-COLUMN($G$2)) + 1)} -> 2 | M25: {=INDEX($D$2:$D$701, (ROW()-ROW($G$2))*7 + (COLUMN()-COLUMN($G$2)) + 1)} -> 0 | O25: =IF(H25=MAX(Tabelle4[[#This Row],[d32_el2_dl2_ff128-ep500]:[d64_el3_dl3_ff128-ep1000]]),1,0) -> 0 | P25: =IF(I25=MAX(Tabelle4[[#This Row],[d32_el2_dl2_ff128-ep500]:[d64_el3_dl3_ff128-ep1000]]),1,0) -> 1 | Q25: =IF(J25=MAX(Tabelle4[[#This Row],[d32_el2_dl2_ff128-ep500]:[d64_el3_dl3_ff128-ep1000]]),1,0) -> 0 | R25: =IF(K25=MAX(Tabelle4[[#This Row],[d32_el2_dl2_ff128-ep500]:[d64_el3_dl3_ff128-ep1000]]),1,0) -> 0 | S25: =IF(L25=MAX(Tabelle4[[#This Row],[d32_el2_dl2_ff128-ep500]:[d64_el3_dl3_ff128-ep1000]]),1,0) -> 0 | T25: =IF(M25=MAX(Tabelle4[[#This Row],[d32_el2_dl2_ff128-ep500]:[d64_el3_dl3_ff128-ep1000]]),1,0) -> 0 | V25: =IF(H25=MIN(Tabelle4[[#This Row],[d32_el2_dl2_ff128-ep500]:[d64_el3_dl3_ff128-ep1000]]),1,0) -> 1 | W25: =IF(I25=MIN(Tabelle4[[#This Row],[d32_el2_dl2_ff128-ep500]:[d64_el3_dl3_ff128-ep1000]]),1,0) -> 0 | X25: =IF(J25=MIN(Tabelle4[[#This Row],[d32_el2_dl2_ff128-ep500]:[d64_el3_dl3_ff128-ep1000]]),1,0) -> 0 | Y25: =IF(K25=MIN(Tabelle4[[#This Row],[d32_el2_dl2_ff128-ep500]:[d64_el3_dl3_ff128-ep1000]]),1,0) -> 0 | Z25: =IF(L25=MIN(Tabelle4[[#This Row],[d32_el2_dl2_ff128-ep500]:[d64_el3_dl3_ff128-ep1000]]),1,0) -> 0 | AA25: =IF(M25=MIN(Tabelle4[[#This Row],[d32_el2_dl2_ff128-ep500]:[d64_el3_dl3_ff128-ep1000]]),1,0) -> 1
A26: 3 | B26: d64_el2_dl2_ff64-ep500 | C26: ['kann', 'helfen'] | D26: 7 | E26: =D26+E19 -> 24 | G26: 25 | H26: {=INDEX($D$2:$D$701, (ROW()-ROW($G$2))*7 + (COLUMN()-COLUMN($G$2)) + 1)} -> 10 | I26: {=INDEX($D$2:$D$701, (ROW()-ROW($G$2))*7 + (COLUMN()-COLUMN($G$2)) + 1)} -> 10 | J26: {=INDEX($D$2:$D$701, (ROW()-ROW($G$2))*7 + (COLUMN()-COLUMN($G$2)) + 1)} -> 10 | K26: {=INDEX($D$2:$D$701, (ROW()-ROW($G$2))*7 + (COLUMN()-COLUMN($G$2)) + 1)} -> 10 | L26: {=INDEX($D$2:$D$701, (ROW()-ROW($G$2))*7 + (COLUMN()-COLUMN($G$2)) + 1)} -> 10 | M26: {=INDEX($D$2:$D$701, (ROW()-ROW($G$2))*7 + (COLUMN()-COLUMN($G$2)) + 1)} -> 10 | O26: =IF(H26=MAX(Tabelle4[[#This Row],[d32_el2_dl2_ff128-ep500]:[d64_el3_dl3_ff128-ep1000]]),1,0) -> 1 | P26: =IF(I26=MAX(Tabelle4[[#This Row],[d32_el2_dl2_ff128-ep500]:[d64_el3_dl3_ff128-ep1000]]),1,0) -> 1 | Q26: =IF(J26=MAX(Tabelle4[[#This Row],[d32_el2_dl2_ff128-ep500]:[d64_el3_dl3_ff128-ep1000]]),1,0) -> 1 | R26: =IF(K26=MAX(Tabelle4[[#This Row],[d32_el2_dl2_ff128-ep500]:[d64_el3_dl3_ff128-ep1000]]),1,0) -> 1 | S26: =IF(L26=MAX(Tabelle4[[#This Row],[d32_el2_dl2_ff128-ep500]:[d64_el3_dl3_ff128-ep1000]]),1,0) -> 1 | T26: =IF(M26=MAX(Tabelle4[[#This Row],[d32_el2_dl2_ff128-ep500]:[d64_el3_dl3_ff128-ep1000]]),1,0) -> 1 | V26: =IF(H26=MIN(Tabelle4[[#This Row],[d32_el2_dl2_ff128-ep500]:[d64_el3_dl3_ff128-ep1000]]),1,0) -> 1 | W26: =IF(I26=MIN(Tabelle4[[#This Row],[d32_el2_dl2_ff128-ep500]:[d64_el3_dl3_ff128-ep1000]]),1,0) -> 1 | X26: =IF(J26=MIN(Tabelle4[[#This Row],[d32_el2_dl2_ff128-ep500]:[d64_el3_dl3_ff128-ep1000]]),1,0) -> 1 | Y26: =IF(K26=MIN(Tabelle4[[#This Row],[d32_el2_dl2_ff128-ep500]:[d64_el3_dl3_ff128-ep1000]]),1,0) -> 1 | Z26: =IF(L26=MIN(Tabelle4[[#This Row],[d32_el2_dl2_ff128-ep500]:[d64_el3_dl3_ff128-ep1000]]),1,0) -> 1 | AA26: =IF(M26=MIN(Tabelle4[[#This Row],[d32_el2_dl2_ff128-ep500]:[d64_el3_dl3_ff128-ep1000]]),1,0) -> 1
A27: 4 | B27: d64_el2_dl2_ff64-ep1000 | C27: ['kann', 'helfen'] | D27: 7 | E27: =D27+E20 -> 24 | G27: 26 | H27: {=INDEX($D$2:$D$701, (ROW()-ROW($G$2))*7 + (COLUMN()-COLUMN($G$2)) + 1)} -> 10 | I27: {=INDEX($D$2:$D$701, (ROW()-ROW($G$2))*7 + (COLUMN()-COLUMN($G$2)) + 1)} -> 6 | J27: {=INDEX($D$2:$D$701, (ROW()-ROW($G$2))*7 + (COLUMN()-COLUMN($G$2)) + 1)} -> 10 | K27: {=INDEX($D$2:$D$701, (ROW()-ROW($G$2))*7 + (COLUMN()-COLUMN($G$2)) + 1)} -> 10 | L27: {=INDEX($D$2:$D$701, (ROW()-ROW($G$2))*7 + (COLUMN()-COLUMN($G$2)) + 1)} -> 10 | M27: {=INDEX($D$2:$D$701, (ROW()-ROW($G$2))*7 + (COLUMN()-COLUMN($G$2)) + 1)} -> 10 | O27: =IF(H27=MAX(Tabelle4[[#This Row],[d32_el2_dl2_ff128-ep500]:[d64_el3_dl3_ff128-ep1000]]),1,0) -> 1 | P27: =IF(I27=MAX(Tabelle4[[#This Row],[d32_el2_dl2_ff128-ep500]:[d64_el3_dl3_ff128-ep1000]]),1,0) -> 0 | Q27: =IF(J27=MAX(Tabelle4[[#This Row],[d32_el2_dl2_ff128-ep500]:[d64_el3_dl3_ff128-ep1000]]),1,0) -> 1 | R27: =IF(K27=MAX(Tabelle4[[#This Row],[d32_el2_dl2_ff128-ep500]:[d64_el3_dl3_ff128-ep1000]]),1,0) -> 1 | S27: =IF(L27=MAX(Tabelle4[[#This Row],[d32_el2_dl2_ff128-ep500]:[d64_el3_dl3_ff128-ep1000]]),1,0) -> 1 | T27: =IF(M27=MAX(Tabelle4[[#This Row],[d32_el2_dl2_ff128-ep500]:[d64_el3_dl3_ff128-ep1000]]),1,0) -> 1 | V27: =IF(H27=MIN(Tabelle4[[#This Row],[d32_el2_dl2_ff128-ep500]:[d64_el3_dl3_ff128-ep1000]]),1,0) -> 0 | W27: =IF(I27=MIN(Tabelle4[[#This Row],[d32_el2_dl2_ff128-ep500]:[d64_el3_dl3_ff128-ep1000]]),1,0) -> 1 | X27: =IF(J27=MIN(Tabelle4[[#This Row],[d32_el2_dl2_ff128-ep500]:[d64_el3_dl3_ff128-ep1000]]),1,0) -> 0 | Y27: =IF(K27=MIN(Tabelle4[[#This Row],[d32_el2_dl2_ff128-ep500]:[d64_el3_dl3_ff128-ep1000]]),1,0) -> 0 | Z27: =IF(L27=MIN(Tabelle4[[#This Row],[d32_el2_dl2_ff128-ep500]:[d64_el3_dl3_ff128-ep1000]]),1,0) -> 0 | AA27: =IF(M27=MIN(Tabelle4[[#This Row],[d32_el2_dl2_ff128-ep500]:[d64_el3_dl3_ff128-ep1000]]),1,0) -> 0
A28: 5 | B28: d64_el2_dl2_ff128-ep1000 | C28: ['helfen'] | D28: 5 | E28: =D28+E21 -> 22 | G28: 27 | H28: {=INDEX($D$2:$D$701, (ROW()-ROW($G$2))*7 + (COLUMN()-COLUMN($G$2)) + 1)} -> 8 | I28: {=INDEX($D$2:$D$701, (ROW()-ROW($G$2))*7 + (COLUMN()-COLUMN($G$2)) + 1)} -> 9 | J28: {=INDEX($D$2:$D$701, (ROW()-ROW($G$2))*7 + (COLUMN()-COLUMN($G$2)) + 1)} -> 10 | K28: {=INDEX($D$2:$D$701, (ROW()-ROW($G$2))*7 + (COLUMN()-COLUMN($G$2)) + 1)} -> 9 | L28: {=INDEX($D$2:$D$701, (ROW()-ROW($G$2))*7 + (COLUMN()-COLUMN($G$2)) + 1)} -> 3 | M28: {=INDEX($D$2:$D$701, (ROW()-ROW($G$2))*7 + (COLUMN()-COLUMN($G$2)) + 1)} -> 10 | O28: =IF(H28=MAX(Tabelle4[[#This Row],[d32_el2_dl2_ff128-ep500]:[d64_el3_dl3_ff128-ep1000]]),1,0) -> 0 | P28: =IF(I28=MAX(Tabelle4[[#This Row],[d32_el2_dl2_ff128-ep500]:[d64_el3_dl3_ff128-ep1000]]),1,0) -> 0 | Q28: =IF(J28=MAX(Tabelle4[[#This Row],[d32_el2_dl2_ff128-ep500]:[d64_el3_dl3_ff128-ep1000]]),1,0) -> 1 | R28: =IF(K28=MAX(Tabelle4[[#This Row],[d32_el2_dl2_ff128-ep500]:[d64_el3_dl3_ff128-ep1000]]),1,0) -> 0 | S28: =IF(L28=MAX(Tabelle4[[#This Row],[d32_el2_dl2_ff128-ep500]:[d64_el3_dl3_ff128-ep1000]]),1,0) -> 0 | T28: =IF(M28=MAX(Tabelle4[[#This Row],[d32_el2_dl2_ff128-ep500]:[d64_el3_dl3_ff128-ep1000]]),1,0) -> 1 | V28: =IF(H28=MIN(Tabelle4[[#This Row],[d32_el2_dl2_ff128-ep500]:[d64_el3_dl3_ff128-ep1000]]),1,0) -> 0 | W28: =IF(I28=MIN(Tabelle4[[#This Row],[d32_el2_dl2_ff128-ep500]:[d64_el3_dl3_ff128-ep1000]]),1,0) -> 0 | X28: =IF(J28=MIN(Tabelle4[[#This Row],[d32_el2_dl2_ff128-ep500]:[d64_el3_dl3_ff128-ep1000]]),1,0) -> 0 | Y28: =IF(K28=MIN(Tabelle4[[#This Row],[d32_el2_dl2_ff128-ep500]:[d64_el3_dl3_ff128-ep1000]]),1,0) -> 0 | Z28: =IF(L28=MIN(Tabelle4[[#This Row],[d32_el2_dl2_ff128-ep500]:[d64_el3_dl3_ff128-ep1000]]),1,0) -> 1 | AA28: =IF(M28=MIN(Tabelle4[[#This Row],[d32_el2_dl2_ff128-ep500]:[d64_el3_dl3_ff128-ep1000]]),1,0) -> 0
A29: 6 | B29: d64_el3_dl3_ff128-ep1000 | C29: ['kann', 'bitte', 'helfen', 'bitte'] | D29: 10 | E29: =D29+E22 -> 25 | G29: 28 | H29: {=INDEX($D$2:$D$701, (ROW()-ROW($G$2))*7 + (COLUMN()-COLUMN($G$2)) + 1)} -> 10 | I29: {=INDEX($D$2:$D$701, (ROW()-ROW($G$2))*7 + (COLUMN()-COLUMN($G$2)) + 1)} -> 10 | J29: {=INDEX($D$2:$D$701, (ROW()-ROW($G$2))*7 + (COLUMN()-COLUMN($G$2)) + 1)} -> 10 | K29: {=INDEX($D$2:$D$701, (ROW()-ROW($G$2))*7 + (COLUMN()-COLUMN($G$2)) + 1)} -> 10 | L29: {=INDEX($D$2:$D$701, (ROW()-ROW($G$2))*7 + (COLUMN()-COLUMN($G$2)) + 1)} -> 7 | M29: {=INDEX($D$2:$D$701, (ROW()-ROW($G$2))*7 + (COLUMN()-COLUMN($G$2)) + 1)} -> 9 | O29: =IF(H29=MAX(Tabelle4[[#This Row],[d32_el2_dl2_ff128-ep500]:[d64_el3_dl3_ff128-ep1000]]),1,0) -> 1 | P29: =IF(I29=MAX(Tabelle4[[#This Row],[d32_el2_dl2_ff128-ep500]:[d64_el3_dl3_ff128-ep1000]]),1,0) -> 1 | Q29: =IF(J29=MAX(Tabelle4[[#This Row],[d32_el2_dl2_ff128-ep500]:[d64_el3_dl3_ff128-ep1000]]),1,0) -> 1 | R29: =IF(K29=MAX(Tabelle4[[#This Row],[d32_el2_dl2_ff128-ep500]:[d64_el3_dl3_ff128-ep1000]]),1,0) -> 1 | S29: =IF(L29=MAX(Tabelle4[[#This Row],[d32_el2_dl2_ff128-ep500]:[d64_el3_dl3_ff128-ep1000]]),1,0) -> 0 | T29: =IF(M29=MAX(Tabelle4[[#This Row],[d32_el2_dl2_ff128-ep500]:[d64_el3_dl3_ff128-ep1000]]),1,0) -> 0 | V29: =IF(H29=MIN(Tabelle4[[#This Row],[d32_el2_dl2_ff128-ep500]:[d64_el3_dl3_ff128-ep1000]]),1,0) -> 0 | W29: =IF(I29=MIN(Tabelle4[[#This Row],[d32_el2_dl2_ff128-ep500]:[d64_el3_dl3_ff128-ep1000]]),1,0) -> 0 | X29: =IF(J29=MIN(Tabelle4[[#This Row],[d32_el2_dl2_ff128-ep500]:[d64_el3_dl3_ff128-ep1000]]),1,0) -> 0 | Y29: =IF(K29=MIN(Tabelle4[[#This Row],[d32_el2_dl2_ff128-ep500]:[d64_el3_dl3_ff128-ep1000]]),1,0) -> 0 | Z29: =IF(L29=MIN(Tabelle4[[#This Row],[d32_el2_dl2_ff128-ep500]:[d64_el3_dl3_ff128-ep1000]]),1,0) -> 1 | AA29: =IF(M29=MIN(Tabelle4[[#This Row],[d32_el2_dl2_ff128-ep500]:[d64_el3_dl3_ff128-ep1000]]),1,0) -> 0
A30: 0 | B30: 5 | C30: Was gibt es heute zu essen? | E30: =D30+E23 -> 0 | G30: 29 | H30: {=INDEX($D$2:$D$701, (ROW()-ROW($G$2))*7 + (COLUMN()-COLUMN($G$2)) + 1)} -> 6 | I30: {=INDEX($D$2:$D$701, (ROW()-ROW($G$2))*7 + (COLUMN()-COLUMN($G$2)) + 1)} -> 8 | J30: {=INDEX($D$2:$D$701, (ROW()-ROW($G$2))*7 + (COLUMN()-COLUMN($G$2)) + 1)} -> 2 | K30: {=INDEX($D$2:$D$701, (ROW()-ROW($G$2))*7 + (COLUMN()-COLUMN($G$2)) + 1)} -> 2 | L30: {=INDEX($D$2:$D$701, (ROW()-ROW($G$2))*7 + (COLUMN()-COLUMN($G$2)) + 1)} -> 0 | M30: {=INDEX($D$2:$D$701, (ROW()-ROW($G$2))*7 + (COLUMN()-COLUMN($G$2)) + 1)} -> 0 | O30: =IF(H30=MAX(Tabelle4[[#This Row],[d32_el2_dl2_ff128-ep500]:[d64_el3_dl3_ff128-ep1000]]),1,0) -> 0 | P30: =IF(I30=MAX(Tabelle4[[#This Row],[d32_el2_dl2_ff128-ep500]:[d64_el3_dl3_ff128-ep1000]]),1,0) -> 1 | Q30: =IF(J30=MAX(Tabelle4[[#This Row],[d32_el2_dl2_ff128-ep500]:[d64_el3_dl3_ff128-ep1000]]),1,0) -> 0 | R30: =IF(K30=MAX(Tabelle4[[#This Row],[d32_el2_dl2_ff128-ep500]:[d64_el3_dl3_ff128-ep1000]]),1,0) -> 0 | S30: =IF(L30=MAX(Tabelle4[[#This Row],[d32_el2_dl2_ff128-ep500]:[d64_el3_dl3_ff128-ep1000]]),1,0) -> 0 | T30: =IF(M30=MAX(Tabelle4[[#This Row],[d32_el2_dl2_ff128-ep500]:[d64_el3_dl3_ff128-ep1000]]),1,0) -> 0 | V30: =IF(H30=MIN(Tabelle4[[#This Row],[d32_el2_dl2_ff128-ep500]:[d64_el3_dl3_ff128-ep1000]]),1,0) -> 0 | W30: =IF(I30=MIN(Tabelle4[[#This Row],[d32_el2_dl2_ff128-ep500]:[d64_el3_dl3_ff128-ep1000]]),1,0) -> 0 | X30: =IF(J30=MIN(Tabelle4[[#This Row],[d32_el2_dl2_ff128-ep500]:[d64_el3_dl3_ff128-ep1000]]),1,0) -> 0 | Y30: =IF(K30=MIN(Tabelle4[[#This Row],[d32_el2_dl2_ff128-ep500]:[d64_el3_dl3_ff128-ep1000]]),1,0) -> 0 | Z30: =IF(L30=MIN(Tabelle4[[#This Row],[d32_el2_dl2_ff128-ep500]:[d64_el3_dl3_ff128-ep1000]]),1,0) -> 1 | AA30: =IF(M30=MIN(Tabelle4[[#This Row],[d32_el2_dl2_ff128-ep500]:[d64_el3_dl3_ff128-ep1000]]),1,0) -> 1
A31: 1 | B31: d32_el2_dl2_ff128-ep500 | C31: ['heute', 'essen', 'heute'] | D31: 9 | E31: =D31+E24 -> 33 | G31: 30 | H31: {=INDEX($D$2:$D$701, (ROW()-ROW($G$2))*7 + (COLUMN()-COLUMN($G$2)) + 1)} -> 10 | I31: {=INDEX($D$2:$D$701, (ROW()-ROW($G$2))*7 + (COLUMN()-COLUMN($G$2)) + 1)} -> 10 | J31: {=INDEX($D$2:$D$701, (ROW()-ROW($G$2))*7 + (COLUMN()-COLUMN($G$2)) + 1)} -> 10 | K31: {=INDEX($D$2:$D$701, (ROW()-ROW($G$2))*7 + (COLUMN()-COLUMN($G$2)) + 1)} -> 10 | L31: {=INDEX($D$2:$D$701, (ROW()-ROW($G$2))*7 + (COLUMN()-COLUMN($G$2)) + 1)} -> 10 | M31: {=INDEX($D$2:$D$701, (ROW()-ROW($G$2))*7 + (COLUMN()-COLUMN($G$2)) + 1)} -> 10 | O31: =IF(H31=MAX(Tabelle4[[#This Row],[d32_el2_dl2_ff128-ep500]:[d64_el3_dl3_ff128-ep1000]]),1,0) -> 1 | P31: =IF(I31=MAX(Tabelle4[[#This Row],[d32_el2_dl2_ff128-ep500]:[d64_el3_dl3_ff128-ep1000]]),1,0) -> 1 | Q31: =IF(J31=MAX(Tabelle4[[#This Row],[d32_el2_dl2_ff128-ep500]:[d64_el3_dl3_ff128-ep1000]]),1,0) -> 1 | R31: =IF(K31=MAX(Tabelle4[[#This Row],[d32_el2_dl2_ff128-ep500]:[d64_el3_dl3_ff128-ep1000]]),1,0) -> 1 | S31: =IF(L31=MAX(Tabelle4[[#This Row],[d32_el2_dl2_ff128-ep500]:[d64_el3_dl3_ff128-ep1000]]),1,0) -> 1 | T31: =IF(M31=MAX(Tabelle4[[#This Row],[d32_el2_dl2_ff128-ep500]:[d64_el3_dl3_ff128-ep1000]]),1,0) -> 1 | V31: =IF(H31=MIN(Tabelle4[[#This Row],[d32_el2_dl2_ff128-ep500]:[d64_el3_dl3_ff128-ep1000]]),1,0) -> 1 | W31: =IF(I31=MIN(Tabelle4[[#This Row],[d32_el2_dl2_ff128-ep500]:[d64_el3_dl3_ff128-ep1000]]),1,0) -> 1 | X31: =IF(J31=MIN(Tabelle4[[#This Row],[d32_el2_dl2_ff128-ep500]:[d64_el3_dl3_ff128-ep1000]]),1,0) -> 1 | Y31: =IF(K31=MIN(Tabelle4[[#This Row],[d32_el2_dl2_ff128-ep500]:[d64_el3_dl3_ff128-ep1000]]),1,0) -> 1 | Z31: =IF(L31=MIN(Tabelle4[[#This Row],[d32_el2_dl2_ff128-ep500]:[d64_el3_dl3_ff128-ep1000]]),1,0) -> 1 | AA31: =IF(M31=MIN(Tabelle4[[#This Row],[d32_el2_dl2_ff128-ep500]:[d64_el3_dl3_ff128-ep1000]]),1,0) -> 1
A32: 2 | B32: d64_el1_dl1_ff64-ep1000 | C32: ['heute', 'essen', 'heute', 'essen'] | D32: 8 | E32: =D32+E25 -> 26 | G32: 31 | H32: {=INDEX($D$2:$D$701, (ROW()-ROW($G$2))*7 + (COLUMN()-COLUMN($G$2)) + 1)} -> 6 | I32: {=INDEX($D$2:$D$701, (ROW()-ROW($G$2))*7 + (COLUMN()-COLUMN($G$2)) + 1)} -> 10 | J32: {=INDEX($D$2:$D$701, (ROW()-ROW($G$2))*7 + (COLUMN()-COLUMN($G$2)) + 1)} -> 8 | K32: {=INDEX($D$2:$D$701, (ROW()-ROW($G$2))*7 + (COLUMN()-COLUMN($G$2)) + 1)} -> 8 | L32: {=INDEX($D$2:$D$701, (ROW()-ROW($G$2))*7 + (COLUMN()-COLUMN($G$2)) + 1)} -> 9 | M32: {=INDEX($D$2:$D$701, (ROW()-ROW($G$2))*7 + (COLUMN()-COLUMN($G$2)) + 1)} -> 6 | O32: =IF(H32=MAX(Tabelle4[[#This Row],[d32_el2_dl2_ff128-ep500]:[d64_el3_dl3_ff128-ep1000]]),1,0) -> 0 | P32: =IF(I32=MAX(Tabelle4[[#This Row],[d32_el2_dl2_ff128-ep500]:[d64_el3_dl3_ff128-ep1000]]),1,0) -> 1 | Q32: =IF(J32=MAX(Tabelle4[[#This Row],[d32_el2_dl2_ff128-ep500]:[d64_el3_dl3_ff128-ep1000]]),1,0) -> 0 | R32: =IF(K32=MAX(Tabelle4[[#This Row],[d32_el2_dl2_ff128-ep500]:[d64_el3_dl3_ff128-ep1000]]),1,0) -> 0 | S32: =IF(L32=MAX(Tabelle4[[#This Row],[d32_el2_dl2_ff128-ep500]:[d64_el3_dl3_ff128-ep1000]]),1,0) -> 0 | T32: =IF(M32=MAX(Tabelle4[[#This Row],[d32_el2_dl2_ff128-ep500]:[d64_el3_dl3_ff128-ep1000]]),1,0) -> 0 | V32: =IF(H32=MIN(Tabelle4[[#This Row],[d32_el2_dl2_ff128-ep500]:[d64_el3_dl3_ff128-ep1000]]),1,0) -> 1 | W32: =IF(I32=MIN(Tabelle4[[#This Row],[d32_el2_dl2_ff128-ep500]:[d64_el3_dl3_ff128-ep1000]]),1,0) -> 0 | X32: =IF(J32=MIN(Tabelle4[[#This Row],[d32_el2_dl2_ff128-ep500]:[d64_el3_dl3_ff128-ep1000]]),1,0) -> 0 | Y32: =IF(K32=MIN(Tabelle4[[#This Row],[d32_el2_dl2_ff128-ep500]:[d64_el3_dl3_ff128-ep1000]]),1,0) -> 0 | Z32: =IF(L32=MIN(Tabelle4[[#This Row],[d32_el2_dl2_ff128-ep500]:[d64_el3_dl3_ff128-ep1000]]),1,0) -> 0 | AA32: =IF(M32=MIN(Tabelle4[[#This Row],[d32_el2_dl2_ff128-ep500]:[d64_el3_dl3_ff128-ep1000]]),1,0) -> 1
